2022-10-11 22:45:21,544 : INFO : root : Loading config.
2022-10-11 22:45:21,547 : INFO : YamlMultifileConfigLoader : Machine config file #1: config.yaml
2022-10-11 22:45:21,547 : WARNING : ConfigProcessor : Config file in cache changed: c:\trashland_2\config\config.yaml
2022-10-11 22:45:21,547 : INFO : ConfigProcessor : Loading config from file c:\users\tanner\appdata\local\programs\python\python37\lib\site-packages\mpf\mpfconfig.yaml.
2022-10-11 22:45:21,617 : INFO : ConfigProcessor : Loading config: c:\users\tanner\appdata\local\programs\python\python37\lib\site-packages\mpf\mpfconfig.yaml
2022-10-11 22:45:21,617 : INFO : ConfigProcessor : Loading config from file c:\trashland_2\config\config.yaml.
2022-10-11 22:45:21,716 : INFO : ConfigProcessor : Loading config: c:\trashland_2\config\config.yaml
2022-10-11 22:45:21,719 : INFO : ConfigProcessor : Config file cache created: C:\Users\Tanner\AppData\Local\Temp\a6762098cb994b55cb03a478b26022ee.mpf_cache
2022-10-11 22:45:21,784 : INFO : ConfigProcessor : Loading config from cache: C:\Users\Tanner\AppData\Local\Temp\9cf7ccc27b21f4d6162237fadfc53e5a.mpf_cache
2022-10-11 22:45:21,785 : INFO : ConfigProcessor : Loading config from cache: C:\Users\Tanner\AppData\Local\Temp\c215df352878fee5d54f1a5ec5b16e7c.mpf_cache
2022-10-11 22:45:21,786 : INFO : ConfigProcessor : Loading config from cache: C:\Users\Tanner\AppData\Local\Temp\708062243e0edcfa77dd6b1521bd0d4e.mpf_cache
2022-10-11 22:45:21,787 : INFO : ConfigProcessor : Loading config from cache: C:\Users\Tanner\AppData\Local\Temp\c4174472f67f7b070dd6fb437c6feb0c.mpf_cache
2022-10-11 22:45:21,787 : INFO : ConfigProcessor : Loading config from cache: C:\Users\Tanner\AppData\Local\Temp\abaa92c43d134e3392cbb2346e6a16be.mpf_cache
2022-10-11 22:45:21,788 : INFO : ConfigProcessor : Loading config from cache: C:\Users\Tanner\AppData\Local\Temp\fc46d53fcb9fe6b8abf783d9c813390a.mpf_cache
2022-10-11 22:45:21,790 : INFO : Machine : Mission Pinball Framework Core Engine v0.55.0
2022-10-11 22:45:21,790 : INFO : Machine : Command line arguments: {'no_load_cache': False, 'create_config_cache': True, 'bcp': False, 'configfile': ['config.yaml'], 'force_assets_load': False, 'jsonlogging': False, 'logfile': 'logs\\2022-10-11-22-45-21-mpf-DESKTOP-7HNFDQ5.log', 'pause': False, 'production': False, 'text_ui': True, 'loglevel': 15, 'consoleloglevel': 20, 'force_platform': None, 'syslog_address': None, 'mc_file_name': None, 'no_sound': False}
2022-10-11 22:45:21,790 : INFO : Machine : MPF path: c:\users\tanner\appdata\local\programs\python\python37\lib\site-packages\mpf
2022-10-11 22:45:21,790 : INFO : Machine : Machine path: c:\trashland_2
2022-10-11 22:45:21,790 : INFO : Machine : Platform: win32
2022-10-11 22:45:21,790 : INFO : Machine : Python executable location: c:\users\tanner\appdata\local\programs\python\python37\python.exe
2022-10-11 22:45:21,790 : INFO : Machine : Python version: 3.7.8 (64-bit)
2022-10-11 22:45:21,792 : INFO : Machine : Initialise MPF.
2022-10-11 22:45:22,047 : INFO : FAST : Connecting to com9 at 921600bps
2022-10-11 22:45:22,091 : INFO : FAST : Connected! Processor: NET, Board Type: FP-CPU-002-2, Firmware: 01.05
2022-10-11 22:45:22,091 : INFO : EventManager : Event: ======'machine_var_fast_net_firmware'====== Args={'value': '01.05', 'prev_value': None, 'change': True}
2022-10-11 22:45:22,091 : INFO : EventManager : Event: ======'machine_var_fast_net_model'====== Args={'value': 'FP-CPU-002-2', 'prev_value': None, 'change': True}
2022-10-11 22:45:24,458 : WARNING : FAST : Got unexpected message from FAST: -N:24
2022-10-11 22:45:24,458 : WARNING : FAST : Got unexpected message from FAST: -N:25
2022-10-11 22:45:24,458 : WARNING : FAST : Got unexpected message from FAST: -N:29
2022-10-11 22:45:24,458 : WARNING : FAST : Got unexpected message from FAST: -N:2A
2022-10-11 22:45:24,458 : WARNING : FAST : Got unexpected message from FAST: -N:2B
2022-10-11 22:45:24,458 : WARNING : FAST : Got unexpected message from FAST: -N:2C
2022-10-11 22:45:24,458 : WARNING : FAST : Got unexpected message from FAST: -N:30
2022-10-11 22:45:24,458 : WARNING : FAST : Got unexpected message from FAST: -N:38
2022-10-11 22:45:24,458 : WARNING : FAST : Got unexpected message from FAST: -N:39
2022-10-11 22:45:24,458 : WARNING : FAST : Got unexpected message from FAST: -N:3A
2022-10-11 22:45:24,458 : WARNING : FAST : Got unexpected message from FAST: -N:3B
2022-10-11 22:45:24,459 : WARNING : FAST : Got unexpected message from FAST: -N:3C
2022-10-11 22:45:24,459 : WARNING : FAST : Got unexpected message from FAST: -N:40
2022-10-11 22:45:24,459 : WARNING : FAST : Got unexpected message from FAST: -N:55
2022-10-11 22:45:24,459 : WARNING : FAST : Got unexpected message from FAST: -N:05
2022-10-11 22:45:24,459 : WARNING : FAST : Got unexpected message from FAST: /N:05
2022-10-11 22:45:24,459 : WARNING : FAST : Got unexpected message from FAST: -N:05
2022-10-11 22:45:24,459 : WARNING : FAST : Got unexpected message from FAST: /N:05
2022-10-11 22:45:24,489 : INFO : FAST : Connecting to com10 at 921600bps
2022-10-11 22:45:24,521 : INFO : FAST : Connected! Processor: RGB, Board Type: FP-CPU-002-2, Firmware: 00.87
2022-10-11 22:45:24,521 : INFO : EventManager : Event: ======'machine_var_fast_rgb_firmware'====== Args={'value': '00.87', 'prev_value': None, 'change': True}
2022-10-11 22:45:24,521 : INFO : EventManager : Event: ======'machine_var_fast_rgb_model'====== Args={'value': 'FP-CPU-002-2', 'prev_value': None, 'change': True}
2022-10-11 22:45:24,522 : INFO : EventManager : Event: ======'machine_var_credits_string'====== Args={'value': 'FREE PLAY', 'prev_value': None, 'change': True}
2022-10-11 22:45:24,566 : INFO : EventManager : Event: ======'machine_var_master_volume'====== Args={'value': 0.5, 'prev_value': None, 'change': True}
2022-10-11 22:45:24,566 : INFO : EventManager : Event: ======'machine_var_mpf_version'====== Args={'value': 'MPF v0.55.0', 'prev_value': None, 'change': True}
2022-10-11 22:45:24,566 : INFO : EventManager : Event: ======'machine_var_mpf_extended_version'====== Args={'value': 'MPF v0.55.0, Config version:5, Show version: 5, BCP version:1.1', 'prev_value': None, 'change': True}
2022-10-11 22:45:24,566 : INFO : EventManager : Event: ======'machine_var_python_version'====== Args={'value': '3.7.8', 'prev_value': None, 'change': True}
2022-10-11 22:45:24,567 : INFO : EventManager : Event: ======'machine_var_platform'====== Args={'value': 'Windows-10-10.0.19041-SP0', 'prev_value': None, 'change': True}
2022-10-11 22:45:24,567 : INFO : EventManager : Event: ======'machine_var_platform_system'====== Args={'value': 'Windows', 'prev_value': None, 'change': True}
2022-10-11 22:45:24,567 : INFO : EventManager : Event: ======'machine_var_platform_release'====== Args={'value': '10', 'prev_value': None, 'change': True}
2022-10-11 22:45:24,567 : INFO : EventManager : Event: ======'machine_var_platform_version'====== Args={'value': '10.0.19041', 'prev_value': None, 'change': True}
2022-10-11 22:45:24,567 : INFO : EventManager : Event: ======'machine_var_platform_machine'====== Args={'value': 'AMD64', 'prev_value': None, 'change': True}
2022-10-11 22:45:24,567 : INFO : EventManager : Event: ======'init_phase_1'====== Args={}
2022-10-11 22:45:24,604 : INFO : EventManager : Event: ======'drop_target_bank_mid_up'====== Args={}
2022-10-11 22:45:24,605 : INFO : EventManager : Event: ======'drop_target_bank_right_up'====== Args={}
2022-10-11 22:45:24,616 : ERROR : asyncio : Task exception was never retrieved
future: <Task finished coro=<SystemWideDevice.device_added_system_wide() done, defined at c:\users\tanner\appdata\local\programs\python\python37\lib\site-packages\mpf\core\system_wide_device.py:15> exception=ConfigFileError('Failed to configure switch s_trough_3 in platform. See error above')>
Traceback (most recent call last):
  File "c:\users\tanner\appdata\local\programs\python\python37\lib\site-packages\mpf\devices\switch.py", line 149, in _initialize
    self.config['number'], config, self.config['platform_settings'])
  File "c:\users\tanner\appdata\local\programs\python\python37\lib\site-packages\mpf\platforms\fast\fast.py", line 665, in configure_switch
    number = self._parse_switch_number(number)
  File "c:\users\tanner\appdata\local\programs\python\python37\lib\site-packages\mpf\platforms\fast\fast.py", line 597, in _parse_switch_number
    raise AssertionError("Board {} does not exist for switch {}".format(board, number))
AssertionError: Board 3 does not exist for switch 3-11

The above exception was the direct cause of the following exception:

Traceback (most recent call last):
  File "c:\users\tanner\appdata\local\programs\python\python37\lib\site-packages\mpf\core\system_wide_device.py", line 17, in device_added_system_wide
    await self._initialize()
  File "c:\users\tanner\appdata\local\programs\python\python37\lib\site-packages\mpf\devices\switch.py", line 152, in _initialize
    self.class_label) from e
mpf.exceptions.config_file_error.ConfigFileError: Config File Error in switch: Failed to configure switch s_trough_3 in platform. See error above Error Code: CFE-switch-2 (https://docs.missionpinball.org/en/0.55/logs/CFE-switch-2.html)
2022-10-11 22:45:24,636 : ERROR : asyncio : Task exception was never retrieved
future: <Task finished coro=<SystemWideDevice.device_added_system_wide() done, defined at c:\users\tanner\appdata\local\programs\python\python37\lib\site-packages\mpf\core\system_wide_device.py:15> exception=ConfigFileError('Failed to configure switch s_eos_left_top in platform. See error above')>
Traceback (most recent call last):
  File "c:\users\tanner\appdata\local\programs\python\python37\lib\site-packages\mpf\devices\switch.py", line 149, in _initialize
    self.config['number'], config, self.config['platform_settings'])
  File "c:\users\tanner\appdata\local\programs\python\python37\lib\site-packages\mpf\platforms\fast\fast.py", line 665, in configure_switch
    number = self._parse_switch_number(number)
  File "c:\users\tanner\appdata\local\programs\python\python37\lib\site-packages\mpf\platforms\fast\fast.py", line 597, in _parse_switch_number
    raise AssertionError("Board {} does not exist for switch {}".format(board, number))
AssertionError: Board 3 does not exist for switch 3-0

The above exception was the direct cause of the following exception:

Traceback (most recent call last):
  File "c:\users\tanner\appdata\local\programs\python\python37\lib\site-packages\mpf\core\system_wide_device.py", line 17, in device_added_system_wide
    await self._initialize()
  File "c:\users\tanner\appdata\local\programs\python\python37\lib\site-packages\mpf\devices\switch.py", line 152, in _initialize
    self.class_label) from e
mpf.exceptions.config_file_error.ConfigFileError: Config File Error in switch: Failed to configure switch s_eos_left_top in platform. See error above Error Code: CFE-switch-2 (https://docs.missionpinball.org/en/0.55/logs/CFE-switch-2.html)
2022-10-11 22:45:24,637 : ERROR : asyncio : Task exception was never retrieved
future: <Task finished coro=<SystemWideDevice.device_added_system_wide() done, defined at c:\users\tanner\appdata\local\programs\python\python37\lib\site-packages\mpf\core\system_wide_device.py:15> exception=AssertionError('Failed to configure driver c_drop_right_left in platform. See error above')>
Traceback (most recent call last):
  File "c:\users\tanner\appdata\local\programs\python\python37\lib\site-packages\mpf\devices\driver.py", line 107, in _initialize
    self.hw_driver = self.platform.configure_driver(config, self.config['number'], platform_settings)
  File "c:\users\tanner\appdata\local\programs\python\python37\lib\site-packages\mpf\platforms\fast\fast.py", line 533, in configure_driver
    number = self._parse_driver_number(number)
  File "c:\users\tanner\appdata\local\programs\python\python37\lib\site-packages\mpf\platforms\fast\fast.py", line 481, in _parse_driver_number
    raise AssertionError("Board {} does not exist for driver {}".format(board, number))
AssertionError: Board 2 does not exist for driver 2-15

The above exception was the direct cause of the following exception:

Traceback (most recent call last):
  File "c:\users\tanner\appdata\local\programs\python\python37\lib\site-packages\mpf\core\system_wide_device.py", line 17, in device_added_system_wide
    await self._initialize()
  File "c:\users\tanner\appdata\local\programs\python\python37\lib\site-packages\mpf\devices\driver.py", line 109, in _initialize
    raise AssertionError("Failed to configure driver {} in platform. See error above".format(self.name)) from e
AssertionError: Failed to configure driver c_drop_right_left in platform. See error above
2022-10-11 22:45:24,643 : ERROR : asyncio : Task exception was never retrieved
future: <Task finished coro=<SystemWideDevice.device_added_system_wide() done, defined at c:\users\tanner\appdata\local\programs\python\python37\lib\site-packages\mpf\core\system_wide_device.py:15> exception=ConfigFileError('Failed to configure switch s_drop_mid_right in platform. See error above')>
Traceback (most recent call last):
  File "c:\users\tanner\appdata\local\programs\python\python37\lib\site-packages\mpf\devices\switch.py", line 149, in _initialize
    self.config['number'], config, self.config['platform_settings'])
  File "c:\users\tanner\appdata\local\programs\python\python37\lib\site-packages\mpf\platforms\fast\fast.py", line 665, in configure_switch
    number = self._parse_switch_number(number)
  File "c:\users\tanner\appdata\local\programs\python\python37\lib\site-packages\mpf\platforms\fast\fast.py", line 597, in _parse_switch_number
    raise AssertionError("Board {} does not exist for switch {}".format(board, number))
AssertionError: Board 2 does not exist for switch 2-5

The above exception was the direct cause of the following exception:

Traceback (most recent call last):
  File "c:\users\tanner\appdata\local\programs\python\python37\lib\site-packages\mpf\core\system_wide_device.py", line 17, in device_added_system_wide
    await self._initialize()
  File "c:\users\tanner\appdata\local\programs\python\python37\lib\site-packages\mpf\devices\switch.py", line 152, in _initialize
    self.class_label) from e
mpf.exceptions.config_file_error.ConfigFileError: Config File Error in switch: Failed to configure switch s_drop_mid_right in platform. See error above Error Code: CFE-switch-2 (https://docs.missionpinball.org/en/0.55/logs/CFE-switch-2.html)
2022-10-11 22:45:24,643 : ERROR : asyncio : Task exception was never retrieved
future: <Task finished coro=<SystemWideDevice.device_added_system_wide() done, defined at c:\users\tanner\appdata\local\programs\python\python37\lib\site-packages\mpf\core\system_wide_device.py:15> exception=ConfigFileError('Failed to configure switch s_bot_rollover in platform. See error above')>
Traceback (most recent call last):
  File "c:\users\tanner\appdata\local\programs\python\python37\lib\site-packages\mpf\devices\switch.py", line 149, in _initialize
    self.config['number'], config, self.config['platform_settings'])
  File "c:\users\tanner\appdata\local\programs\python\python37\lib\site-packages\mpf\platforms\fast\fast.py", line 665, in configure_switch
    number = self._parse_switch_number(number)
  File "c:\users\tanner\appdata\local\programs\python\python37\lib\site-packages\mpf\platforms\fast\fast.py", line 597, in _parse_switch_number
    raise AssertionError("Board {} does not exist for switch {}".format(board, number))
AssertionError: Board 4 does not exist for switch 4-4

The above exception was the direct cause of the following exception:

Traceback (most recent call last):
  File "c:\users\tanner\appdata\local\programs\python\python37\lib\site-packages\mpf\core\system_wide_device.py", line 17, in device_added_system_wide
    await self._initialize()
  File "c:\users\tanner\appdata\local\programs\python\python37\lib\site-packages\mpf\devices\switch.py", line 152, in _initialize
    self.class_label) from e
mpf.exceptions.config_file_error.ConfigFileError: Config File Error in switch: Failed to configure switch s_bot_rollover in platform. See error above Error Code: CFE-switch-2 (https://docs.missionpinball.org/en/0.55/logs/CFE-switch-2.html)
2022-10-11 22:45:24,644 : ERROR : asyncio : Task exception was never retrieved
future: <Task finished coro=<SystemWideDevice.device_added_system_wide() done, defined at c:\users\tanner\appdata\local\programs\python\python37\lib\site-packages\mpf\core\system_wide_device.py:15> exception=AssertionError('Failed to configure driver c_right_sling in platform. See error above')>
Traceback (most recent call last):
  File "c:\users\tanner\appdata\local\programs\python\python37\lib\site-packages\mpf\devices\driver.py", line 107, in _initialize
    self.hw_driver = self.platform.configure_driver(config, self.config['number'], platform_settings)
  File "c:\users\tanner\appdata\local\programs\python\python37\lib\site-packages\mpf\platforms\fast\fast.py", line 533, in configure_driver
    number = self._parse_driver_number(number)
  File "c:\users\tanner\appdata\local\programs\python\python37\lib\site-packages\mpf\platforms\fast\fast.py", line 481, in _parse_driver_number
    raise AssertionError("Board {} does not exist for driver {}".format(board, number))
AssertionError: Board 2 does not exist for driver 2-6

The above exception was the direct cause of the following exception:

Traceback (most recent call last):
  File "c:\users\tanner\appdata\local\programs\python\python37\lib\site-packages\mpf\core\system_wide_device.py", line 17, in device_added_system_wide
    await self._initialize()
  File "c:\users\tanner\appdata\local\programs\python\python37\lib\site-packages\mpf\devices\driver.py", line 109, in _initialize
    raise AssertionError("Failed to configure driver {} in platform. See error above".format(self.name)) from e
AssertionError: Failed to configure driver c_right_sling in platform. See error above
2022-10-11 22:45:24,644 : ERROR : asyncio : Task exception was never retrieved
future: <Task finished coro=<SystemWideDevice.device_added_system_wide() done, defined at c:\users\tanner\appdata\local\programs\python\python37\lib\site-packages\mpf\core\system_wide_device.py:15> exception=ConfigFileError('Failed to configure switch s_upper_stationary in platform. See error above')>
Traceback (most recent call last):
  File "c:\users\tanner\appdata\local\programs\python\python37\lib\site-packages\mpf\devices\switch.py", line 149, in _initialize
    self.config['number'], config, self.config['platform_settings'])
  File "c:\users\tanner\appdata\local\programs\python\python37\lib\site-packages\mpf\platforms\fast\fast.py", line 665, in configure_switch
    number = self._parse_switch_number(number)
  File "c:\users\tanner\appdata\local\programs\python\python37\lib\site-packages\mpf\platforms\fast\fast.py", line 597, in _parse_switch_number
    raise AssertionError("Board {} does not exist for switch {}".format(board, number))
AssertionError: Board 1 does not exist for switch 1-2

The above exception was the direct cause of the following exception:

Traceback (most recent call last):
  File "c:\users\tanner\appdata\local\programs\python\python37\lib\site-packages\mpf\core\system_wide_device.py", line 17, in device_added_system_wide
    await self._initialize()
  File "c:\users\tanner\appdata\local\programs\python\python37\lib\site-packages\mpf\devices\switch.py", line 152, in _initialize
    self.class_label) from e
mpf.exceptions.config_file_error.ConfigFileError: Config File Error in switch: Failed to configure switch s_upper_stationary in platform. See error above Error Code: CFE-switch-2 (https://docs.missionpinball.org/en/0.55/logs/CFE-switch-2.html)
2022-10-11 22:45:24,645 : ERROR : asyncio : Task exception was never retrieved
future: <Task finished coro=<SystemWideDevice.device_added_system_wide() done, defined at c:\users\tanner\appdata\local\programs\python\python37\lib\site-packages\mpf\core\system_wide_device.py:15> exception=ConfigFileError('Failed to configure switch s_left_flipper in platform. See error above')>
Traceback (most recent call last):
  File "c:\users\tanner\appdata\local\programs\python\python37\lib\site-packages\mpf\devices\switch.py", line 149, in _initialize
    self.config['number'], config, self.config['platform_settings'])
  File "c:\users\tanner\appdata\local\programs\python\python37\lib\site-packages\mpf\platforms\fast\fast.py", line 665, in configure_switch
    number = self._parse_switch_number(number)
  File "c:\users\tanner\appdata\local\programs\python\python37\lib\site-packages\mpf\platforms\fast\fast.py", line 597, in _parse_switch_number
    raise AssertionError("Board {} does not exist for switch {}".format(board, number))
AssertionError: Board 0 does not exist for switch 0-4

The above exception was the direct cause of the following exception:

Traceback (most recent call last):
  File "c:\users\tanner\appdata\local\programs\python\python37\lib\site-packages\mpf\core\system_wide_device.py", line 17, in device_added_system_wide
    await self._initialize()
  File "c:\users\tanner\appdata\local\programs\python\python37\lib\site-packages\mpf\devices\switch.py", line 152, in _initialize
    self.class_label) from e
mpf.exceptions.config_file_error.ConfigFileError: Config File Error in switch: Failed to configure switch s_left_flipper in platform. See error above Error Code: CFE-switch-2 (https://docs.missionpinball.org/en/0.55/logs/CFE-switch-2.html)
2022-10-11 22:45:24,645 : ERROR : asyncio : Task exception was never retrieved
future: <Task finished coro=<SystemWideDevice.device_added_system_wide() done, defined at c:\users\tanner\appdata\local\programs\python\python37\lib\site-packages\mpf\core\system_wide_device.py:15> exception=ConfigFileError('Failed to configure switch s_right_outlane in platform. See error above')>
Traceback (most recent call last):
  File "c:\users\tanner\appdata\local\programs\python\python37\lib\site-packages\mpf\devices\switch.py", line 149, in _initialize
    self.config['number'], config, self.config['platform_settings'])
  File "c:\users\tanner\appdata\local\programs\python\python37\lib\site-packages\mpf\platforms\fast\fast.py", line 665, in configure_switch
    number = self._parse_switch_number(number)
  File "c:\users\tanner\appdata\local\programs\python\python37\lib\site-packages\mpf\platforms\fast\fast.py", line 597, in _parse_switch_number
    raise AssertionError("Board {} does not exist for switch {}".format(board, number))
AssertionError: Board 3 does not exist for switch 3-13

The above exception was the direct cause of the following exception:

Traceback (most recent call last):
  File "c:\users\tanner\appdata\local\programs\python\python37\lib\site-packages\mpf\core\system_wide_device.py", line 17, in device_added_system_wide
    await self._initialize()
  File "c:\users\tanner\appdata\local\programs\python\python37\lib\site-packages\mpf\devices\switch.py", line 152, in _initialize
    self.class_label) from e
mpf.exceptions.config_file_error.ConfigFileError: Config File Error in switch: Failed to configure switch s_right_outlane in platform. See error above Error Code: CFE-switch-2 (https://docs.missionpinball.org/en/0.55/logs/CFE-switch-2.html)
2022-10-11 22:45:24,645 : ERROR : asyncio : Task exception was never retrieved
future: <Task finished coro=<SystemWideDevice.device_added_system_wide() done, defined at c:\users\tanner\appdata\local\programs\python\python37\lib\site-packages\mpf\core\system_wide_device.py:15> exception=AssertionError('Failed to configure driver c_drop_mid in platform. See error above')>
Traceback (most recent call last):
  File "c:\users\tanner\appdata\local\programs\python\python37\lib\site-packages\mpf\devices\driver.py", line 107, in _initialize
    self.hw_driver = self.platform.configure_driver(config, self.config['number'], platform_settings)
  File "c:\users\tanner\appdata\local\programs\python\python37\lib\site-packages\mpf\platforms\fast\fast.py", line 533, in configure_driver
    number = self._parse_driver_number(number)
  File "c:\users\tanner\appdata\local\programs\python\python37\lib\site-packages\mpf\platforms\fast\fast.py", line 481, in _parse_driver_number
    raise AssertionError("Board {} does not exist for driver {}".format(board, number))
AssertionError: Board 2 does not exist for driver 2-5

The above exception was the direct cause of the following exception:

Traceback (most recent call last):
  File "c:\users\tanner\appdata\local\programs\python\python37\lib\site-packages\mpf\core\system_wide_device.py", line 17, in device_added_system_wide
    await self._initialize()
  File "c:\users\tanner\appdata\local\programs\python\python37\lib\site-packages\mpf\devices\driver.py", line 109, in _initialize
    raise AssertionError("Failed to configure driver {} in platform. See error above".format(self.name)) from e
AssertionError: Failed to configure driver c_drop_mid in platform. See error above
2022-10-11 22:45:24,646 : ERROR : asyncio : Task exception was never retrieved
future: <Task finished coro=<SystemWideDevice.device_added_system_wide() done, defined at c:\users\tanner\appdata\local\programs\python\python37\lib\site-packages\mpf\core\system_wide_device.py:15> exception=ConfigFileError('Failed to configure switch s_trough_2 in platform. See error above')>
Traceback (most recent call last):
  File "c:\users\tanner\appdata\local\programs\python\python37\lib\site-packages\mpf\devices\switch.py", line 149, in _initialize
    self.config['number'], config, self.config['platform_settings'])
  File "c:\users\tanner\appdata\local\programs\python\python37\lib\site-packages\mpf\platforms\fast\fast.py", line 665, in configure_switch
    number = self._parse_switch_number(number)
  File "c:\users\tanner\appdata\local\programs\python\python37\lib\site-packages\mpf\platforms\fast\fast.py", line 597, in _parse_switch_number
    raise AssertionError("Board {} does not exist for switch {}".format(board, number))
AssertionError: Board 3 does not exist for switch 3-12

The above exception was the direct cause of the following exception:

Traceback (most recent call last):
  File "c:\users\tanner\appdata\local\programs\python\python37\lib\site-packages\mpf\core\system_wide_device.py", line 17, in device_added_system_wide
    await self._initialize()
  File "c:\users\tanner\appdata\local\programs\python\python37\lib\site-packages\mpf\devices\switch.py", line 152, in _initialize
    self.class_label) from e
mpf.exceptions.config_file_error.ConfigFileError: Config File Error in switch: Failed to configure switch s_trough_2 in platform. See error above Error Code: CFE-switch-2 (https://docs.missionpinball.org/en/0.55/logs/CFE-switch-2.html)
2022-10-11 22:45:24,646 : ERROR : asyncio : Task exception was never retrieved
future: <Task finished coro=<SystemWideDevice.device_added_system_wide() done, defined at c:\users\tanner\appdata\local\programs\python\python37\lib\site-packages\mpf\core\system_wide_device.py:15> exception=ConfigFileError('Failed to configure switch s_drop_mid_mid in platform. See error above')>
Traceback (most recent call last):
  File "c:\users\tanner\appdata\local\programs\python\python37\lib\site-packages\mpf\devices\switch.py", line 149, in _initialize
    self.config['number'], config, self.config['platform_settings'])
  File "c:\users\tanner\appdata\local\programs\python\python37\lib\site-packages\mpf\platforms\fast\fast.py", line 665, in configure_switch
    number = self._parse_switch_number(number)
  File "c:\users\tanner\appdata\local\programs\python\python37\lib\site-packages\mpf\platforms\fast\fast.py", line 597, in _parse_switch_number
    raise AssertionError("Board {} does not exist for switch {}".format(board, number))
AssertionError: Board 2 does not exist for switch 2-4

The above exception was the direct cause of the following exception:

Traceback (most recent call last):
  File "c:\users\tanner\appdata\local\programs\python\python37\lib\site-packages\mpf\core\system_wide_device.py", line 17, in device_added_system_wide
    await self._initialize()
  File "c:\users\tanner\appdata\local\programs\python\python37\lib\site-packages\mpf\devices\switch.py", line 152, in _initialize
    self.class_label) from e
mpf.exceptions.config_file_error.ConfigFileError: Config File Error in switch: Failed to configure switch s_drop_mid_mid in platform. See error above Error Code: CFE-switch-2 (https://docs.missionpinball.org/en/0.55/logs/CFE-switch-2.html)
2022-10-11 22:45:24,646 : ERROR : asyncio : Task exception was never retrieved
future: <Task finished coro=<SystemWideDevice.device_added_system_wide() done, defined at c:\users\tanner\appdata\local\programs\python\python37\lib\site-packages\mpf\core\system_wide_device.py:15> exception=AssertionError('Failed to configure driver c_shaker in platform. See error above')>
Traceback (most recent call last):
  File "c:\users\tanner\appdata\local\programs\python\python37\lib\site-packages\mpf\devices\driver.py", line 107, in _initialize
    self.hw_driver = self.platform.configure_driver(config, self.config['number'], platform_settings)
  File "c:\users\tanner\appdata\local\programs\python\python37\lib\site-packages\mpf\platforms\fast\fast.py", line 533, in configure_driver
    number = self._parse_driver_number(number)
  File "c:\users\tanner\appdata\local\programs\python\python37\lib\site-packages\mpf\platforms\fast\fast.py", line 481, in _parse_driver_number
    raise AssertionError("Board {} does not exist for driver {}".format(board, number))
AssertionError: Board 0 does not exist for driver 0-0

The above exception was the direct cause of the following exception:

Traceback (most recent call last):
  File "c:\users\tanner\appdata\local\programs\python\python37\lib\site-packages\mpf\core\system_wide_device.py", line 17, in device_added_system_wide
    await self._initialize()
  File "c:\users\tanner\appdata\local\programs\python\python37\lib\site-packages\mpf\devices\driver.py", line 109, in _initialize
    raise AssertionError("Failed to configure driver {} in platform. See error above".format(self.name)) from e
AssertionError: Failed to configure driver c_shaker in platform. See error above
2022-10-11 22:45:24,647 : ERROR : asyncio : Task exception was never retrieved
future: <Task finished coro=<SystemWideDevice.device_added_system_wide() done, defined at c:\users\tanner\appdata\local\programs\python\python37\lib\site-packages\mpf\core\system_wide_device.py:15> exception=ConfigFileError('Failed to configure switch s_back_rollover in platform. See error above')>
Traceback (most recent call last):
  File "c:\users\tanner\appdata\local\programs\python\python37\lib\site-packages\mpf\devices\switch.py", line 149, in _initialize
    self.config['number'], config, self.config['platform_settings'])
  File "c:\users\tanner\appdata\local\programs\python\python37\lib\site-packages\mpf\platforms\fast\fast.py", line 665, in configure_switch
    number = self._parse_switch_number(number)
  File "c:\users\tanner\appdata\local\programs\python\python37\lib\site-packages\mpf\platforms\fast\fast.py", line 597, in _parse_switch_number
    raise AssertionError("Board {} does not exist for switch {}".format(board, number))
AssertionError: Board 1 does not exist for switch 1-3

The above exception was the direct cause of the following exception:

Traceback (most recent call last):
  File "c:\users\tanner\appdata\local\programs\python\python37\lib\site-packages\mpf\core\system_wide_device.py", line 17, in device_added_system_wide
    await self._initialize()
  File "c:\users\tanner\appdata\local\programs\python\python37\lib\site-packages\mpf\devices\switch.py", line 152, in _initialize
    self.class_label) from e
mpf.exceptions.config_file_error.ConfigFileError: Config File Error in switch: Failed to configure switch s_back_rollover in platform. See error above Error Code: CFE-switch-2 (https://docs.missionpinball.org/en/0.55/logs/CFE-switch-2.html)
2022-10-11 22:45:24,647 : ERROR : asyncio : Task exception was never retrieved
future: <Task finished coro=<SystemWideDevice.device_added_system_wide() done, defined at c:\users\tanner\appdata\local\programs\python\python37\lib\site-packages\mpf\core\system_wide_device.py:15> exception=ConfigFileError('Failed to configure switch s_bot_vuk in platform. See error above')>
Traceback (most recent call last):
  File "c:\users\tanner\appdata\local\programs\python\python37\lib\site-packages\mpf\devices\switch.py", line 149, in _initialize
    self.config['number'], config, self.config['platform_settings'])
  File "c:\users\tanner\appdata\local\programs\python\python37\lib\site-packages\mpf\platforms\fast\fast.py", line 665, in configure_switch
    number = self._parse_switch_number(number)
  File "c:\users\tanner\appdata\local\programs\python\python37\lib\site-packages\mpf\platforms\fast\fast.py", line 597, in _parse_switch_number
    raise AssertionError("Board {} does not exist for switch {}".format(board, number))
AssertionError: Board 4 does not exist for switch 4-5

The above exception was the direct cause of the following exception:

Traceback (most recent call last):
  File "c:\users\tanner\appdata\local\programs\python\python37\lib\site-packages\mpf\core\system_wide_device.py", line 17, in device_added_system_wide
    await self._initialize()
  File "c:\users\tanner\appdata\local\programs\python\python37\lib\site-packages\mpf\devices\switch.py", line 152, in _initialize
    self.class_label) from e
mpf.exceptions.config_file_error.ConfigFileError: Config File Error in switch: Failed to configure switch s_bot_vuk in platform. See error above Error Code: CFE-switch-2 (https://docs.missionpinball.org/en/0.55/logs/CFE-switch-2.html)
2022-10-11 22:45:24,647 : ERROR : asyncio : Task exception was never retrieved
future: <Task finished coro=<SystemWideDevice.device_added_system_wide() done, defined at c:\users\tanner\appdata\local\programs\python\python37\lib\site-packages\mpf\core\system_wide_device.py:15> exception=AssertionError('Failed to configure driver c_flipper_left in platform. See error above')>
Traceback (most recent call last):
  File "c:\users\tanner\appdata\local\programs\python\python37\lib\site-packages\mpf\devices\driver.py", line 107, in _initialize
    self.hw_driver = self.platform.configure_driver(config, self.config['number'], platform_settings)
  File "c:\users\tanner\appdata\local\programs\python\python37\lib\site-packages\mpf\platforms\fast\fast.py", line 533, in configure_driver
    number = self._parse_driver_number(number)
  File "c:\users\tanner\appdata\local\programs\python\python37\lib\site-packages\mpf\platforms\fast\fast.py", line 481, in _parse_driver_number
    raise AssertionError("Board {} does not exist for driver {}".format(board, number))
AssertionError: Board 3 does not exist for driver 3-4

The above exception was the direct cause of the following exception:

Traceback (most recent call last):
  File "c:\users\tanner\appdata\local\programs\python\python37\lib\site-packages\mpf\core\system_wide_device.py", line 17, in device_added_system_wide
    await self._initialize()
  File "c:\users\tanner\appdata\local\programs\python\python37\lib\site-packages\mpf\devices\driver.py", line 109, in _initialize
    raise AssertionError("Failed to configure driver {} in platform. See error above".format(self.name)) from e
AssertionError: Failed to configure driver c_flipper_left in platform. See error above
2022-10-11 22:45:24,648 : ERROR : asyncio : Task exception was never retrieved
future: <Task finished coro=<SystemWideDevice.device_added_system_wide() done, defined at c:\users\tanner\appdata\local\programs\python\python37\lib\site-packages\mpf\core\system_wide_device.py:15> exception=ConfigFileError('Failed to configure switch s_right_inlane in platform. See error above')>
Traceback (most recent call last):
  File "c:\users\tanner\appdata\local\programs\python\python37\lib\site-packages\mpf\devices\switch.py", line 149, in _initialize
    self.config['number'], config, self.config['platform_settings'])
  File "c:\users\tanner\appdata\local\programs\python\python37\lib\site-packages\mpf\platforms\fast\fast.py", line 665, in configure_switch
    number = self._parse_switch_number(number)
  File "c:\users\tanner\appdata\local\programs\python\python37\lib\site-packages\mpf\platforms\fast\fast.py", line 597, in _parse_switch_number
    raise AssertionError("Board {} does not exist for switch {}".format(board, number))
AssertionError: Board 3 does not exist for switch 3-14

The above exception was the direct cause of the following exception:

Traceback (most recent call last):
  File "c:\users\tanner\appdata\local\programs\python\python37\lib\site-packages\mpf\core\system_wide_device.py", line 17, in device_added_system_wide
    await self._initialize()
  File "c:\users\tanner\appdata\local\programs\python\python37\lib\site-packages\mpf\devices\switch.py", line 152, in _initialize
    self.class_label) from e
mpf.exceptions.config_file_error.ConfigFileError: Config File Error in switch: Failed to configure switch s_right_inlane in platform. See error above Error Code: CFE-switch-2 (https://docs.missionpinball.org/en/0.55/logs/CFE-switch-2.html)
2022-10-11 22:45:24,648 : ERROR : asyncio : Task exception was never retrieved
future: <Task finished coro=<SystemWideDevice.device_added_system_wide() done, defined at c:\users\tanner\appdata\local\programs\python\python37\lib\site-packages\mpf\core\system_wide_device.py:15> exception=AssertionError('Failed to configure driver c_flipper_left_hold in platform. See error above')>
Traceback (most recent call last):
  File "c:\users\tanner\appdata\local\programs\python\python37\lib\site-packages\mpf\devices\driver.py", line 107, in _initialize
    self.hw_driver = self.platform.configure_driver(config, self.config['number'], platform_settings)
  File "c:\users\tanner\appdata\local\programs\python\python37\lib\site-packages\mpf\platforms\fast\fast.py", line 533, in configure_driver
    number = self._parse_driver_number(number)
  File "c:\users\tanner\appdata\local\programs\python\python37\lib\site-packages\mpf\platforms\fast\fast.py", line 481, in _parse_driver_number
    raise AssertionError("Board {} does not exist for driver {}".format(board, number))
AssertionError: Board 3 does not exist for driver 3-5

The above exception was the direct cause of the following exception:

Traceback (most recent call last):
  File "c:\users\tanner\appdata\local\programs\python\python37\lib\site-packages\mpf\core\system_wide_device.py", line 17, in device_added_system_wide
    await self._initialize()
  File "c:\users\tanner\appdata\local\programs\python\python37\lib\site-packages\mpf\devices\driver.py", line 109, in _initialize
    raise AssertionError("Failed to configure driver {} in platform. See error above".format(self.name)) from e
AssertionError: Failed to configure driver c_flipper_left_hold in platform. See error above
2022-10-11 22:45:24,648 : ERROR : asyncio : Task exception was never retrieved
future: <Task finished coro=<SystemWideDevice.device_added_system_wide() done, defined at c:\users\tanner\appdata\local\programs\python\python37\lib\site-packages\mpf\core\system_wide_device.py:15> exception=ConfigFileError('Failed to configure switch s_right_flipper in platform. See error above')>
Traceback (most recent call last):
  File "c:\users\tanner\appdata\local\programs\python\python37\lib\site-packages\mpf\devices\switch.py", line 149, in _initialize
    self.config['number'], config, self.config['platform_settings'])
  File "c:\users\tanner\appdata\local\programs\python\python37\lib\site-packages\mpf\platforms\fast\fast.py", line 665, in configure_switch
    number = self._parse_switch_number(number)
  File "c:\users\tanner\appdata\local\programs\python\python37\lib\site-packages\mpf\platforms\fast\fast.py", line 597, in _parse_switch_number
    raise AssertionError("Board {} does not exist for switch {}".format(board, number))
AssertionError: Board 0 does not exist for switch 0-0

The above exception was the direct cause of the following exception:

Traceback (most recent call last):
  File "c:\users\tanner\appdata\local\programs\python\python37\lib\site-packages\mpf\core\system_wide_device.py", line 17, in device_added_system_wide
    await self._initialize()
  File "c:\users\tanner\appdata\local\programs\python\python37\lib\site-packages\mpf\devices\switch.py", line 152, in _initialize
    self.class_label) from e
mpf.exceptions.config_file_error.ConfigFileError: Config File Error in switch: Failed to configure switch s_right_flipper in platform. See error above Error Code: CFE-switch-2 (https://docs.missionpinball.org/en/0.55/logs/CFE-switch-2.html)
2022-10-11 22:45:24,649 : ERROR : asyncio : Task exception was never retrieved
future: <Task finished coro=<SystemWideDevice.device_added_system_wide() done, defined at c:\users\tanner\appdata\local\programs\python\python37\lib\site-packages\mpf\core\system_wide_device.py:15> exception=ConfigFileError('Failed to configure switch s_drop_mid_left in platform. See error above')>
Traceback (most recent call last):
  File "c:\users\tanner\appdata\local\programs\python\python37\lib\site-packages\mpf\devices\switch.py", line 149, in _initialize
    self.config['number'], config, self.config['platform_settings'])
  File "c:\users\tanner\appdata\local\programs\python\python37\lib\site-packages\mpf\platforms\fast\fast.py", line 665, in configure_switch
    number = self._parse_switch_number(number)
  File "c:\users\tanner\appdata\local\programs\python\python37\lib\site-packages\mpf\platforms\fast\fast.py", line 597, in _parse_switch_number
    raise AssertionError("Board {} does not exist for switch {}".format(board, number))
AssertionError: Board 2 does not exist for switch 2-3

The above exception was the direct cause of the following exception:

Traceback (most recent call last):
  File "c:\users\tanner\appdata\local\programs\python\python37\lib\site-packages\mpf\core\system_wide_device.py", line 17, in device_added_system_wide
    await self._initialize()
  File "c:\users\tanner\appdata\local\programs\python\python37\lib\site-packages\mpf\devices\switch.py", line 152, in _initialize
    self.class_label) from e
mpf.exceptions.config_file_error.ConfigFileError: Config File Error in switch: Failed to configure switch s_drop_mid_left in platform. See error above Error Code: CFE-switch-2 (https://docs.missionpinball.org/en/0.55/logs/CFE-switch-2.html)
2022-10-11 22:45:24,649 : ERROR : asyncio : Task exception was never retrieved
future: <Task finished coro=<SystemWideDevice.device_added_system_wide() done, defined at c:\users\tanner\appdata\local\programs\python\python37\lib\site-packages\mpf\core\system_wide_device.py:15> exception=AssertionError('Failed to configure driver c_pop_left in platform. See error above')>
Traceback (most recent call last):
  File "c:\users\tanner\appdata\local\programs\python\python37\lib\site-packages\mpf\devices\driver.py", line 107, in _initialize
    self.hw_driver = self.platform.configure_driver(config, self.config['number'], platform_settings)
  File "c:\users\tanner\appdata\local\programs\python\python37\lib\site-packages\mpf\platforms\fast\fast.py", line 533, in configure_driver
    number = self._parse_driver_number(number)
  File "c:\users\tanner\appdata\local\programs\python\python37\lib\site-packages\mpf\platforms\fast\fast.py", line 481, in _parse_driver_number
    raise AssertionError("Board {} does not exist for driver {}".format(board, number))
AssertionError: Board 2 does not exist for driver 2-4

The above exception was the direct cause of the following exception:

Traceback (most recent call last):
  File "c:\users\tanner\appdata\local\programs\python\python37\lib\site-packages\mpf\core\system_wide_device.py", line 17, in device_added_system_wide
    await self._initialize()
  File "c:\users\tanner\appdata\local\programs\python\python37\lib\site-packages\mpf\devices\driver.py", line 109, in _initialize
    raise AssertionError("Failed to configure driver {} in platform. See error above".format(self.name)) from e
AssertionError: Failed to configure driver c_pop_left in platform. See error above
2022-10-11 22:45:24,649 : ERROR : asyncio : Task exception was never retrieved
future: <Task finished coro=<SystemWideDevice.device_added_system_wide() done, defined at c:\users\tanner\appdata\local\programs\python\python37\lib\site-packages\mpf\core\system_wide_device.py:15> exception=ConfigFileError('Failed to configure switch s_trough_1 in platform. See error above')>
Traceback (most recent call last):
  File "c:\users\tanner\appdata\local\programs\python\python37\lib\site-packages\mpf\devices\switch.py", line 149, in _initialize
    self.config['number'], config, self.config['platform_settings'])
  File "c:\users\tanner\appdata\local\programs\python\python37\lib\site-packages\mpf\platforms\fast\fast.py", line 665, in configure_switch
    number = self._parse_switch_number(number)
  File "c:\users\tanner\appdata\local\programs\python\python37\lib\site-packages\mpf\platforms\fast\fast.py", line 597, in _parse_switch_number
    raise AssertionError("Board {} does not exist for switch {}".format(board, number))
AssertionError: Board 3 does not exist for switch 3-16

The above exception was the direct cause of the following exception:

Traceback (most recent call last):
  File "c:\users\tanner\appdata\local\programs\python\python37\lib\site-packages\mpf\core\system_wide_device.py", line 17, in device_added_system_wide
    await self._initialize()
  File "c:\users\tanner\appdata\local\programs\python\python37\lib\site-packages\mpf\devices\switch.py", line 152, in _initialize
    self.class_label) from e
mpf.exceptions.config_file_error.ConfigFileError: Config File Error in switch: Failed to configure switch s_trough_1 in platform. See error above Error Code: CFE-switch-2 (https://docs.missionpinball.org/en/0.55/logs/CFE-switch-2.html)
2022-10-11 22:45:24,650 : ERROR : asyncio : Task exception was never retrieved
future: <Task finished coro=<SystemWideDevice.device_added_system_wide() done, defined at c:\users\tanner\appdata\local\programs\python\python37\lib\site-packages\mpf\core\system_wide_device.py:15> exception=ConfigFileError('Failed to configure switch s_back_pop in platform. See error above')>
Traceback (most recent call last):
  File "c:\users\tanner\appdata\local\programs\python\python37\lib\site-packages\mpf\devices\switch.py", line 149, in _initialize
    self.config['number'], config, self.config['platform_settings'])
  File "c:\users\tanner\appdata\local\programs\python\python37\lib\site-packages\mpf\platforms\fast\fast.py", line 665, in configure_switch
    number = self._parse_switch_number(number)
  File "c:\users\tanner\appdata\local\programs\python\python37\lib\site-packages\mpf\platforms\fast\fast.py", line 597, in _parse_switch_number
    raise AssertionError("Board {} does not exist for switch {}".format(board, number))
AssertionError: Board 1 does not exist for switch 1-4

The above exception was the direct cause of the following exception:

Traceback (most recent call last):
  File "c:\users\tanner\appdata\local\programs\python\python37\lib\site-packages\mpf\core\system_wide_device.py", line 17, in device_added_system_wide
    await self._initialize()
  File "c:\users\tanner\appdata\local\programs\python\python37\lib\site-packages\mpf\devices\switch.py", line 152, in _initialize
    self.class_label) from e
mpf.exceptions.config_file_error.ConfigFileError: Config File Error in switch: Failed to configure switch s_back_pop in platform. See error above Error Code: CFE-switch-2 (https://docs.missionpinball.org/en/0.55/logs/CFE-switch-2.html)
2022-10-11 22:45:24,650 : ERROR : asyncio : Task exception was never retrieved
future: <Task finished coro=<SystemWideDevice.device_added_system_wide() done, defined at c:\users\tanner\appdata\local\programs\python\python37\lib\site-packages\mpf\core\system_wide_device.py:15> exception=AssertionError('Failed to configure driver c_flipper_right in platform. See error above')>
Traceback (most recent call last):
  File "c:\users\tanner\appdata\local\programs\python\python37\lib\site-packages\mpf\devices\driver.py", line 107, in _initialize
    self.hw_driver = self.platform.configure_driver(config, self.config['number'], platform_settings)
  File "c:\users\tanner\appdata\local\programs\python\python37\lib\site-packages\mpf\platforms\fast\fast.py", line 533, in configure_driver
    number = self._parse_driver_number(number)
  File "c:\users\tanner\appdata\local\programs\python\python37\lib\site-packages\mpf\platforms\fast\fast.py", line 481, in _parse_driver_number
    raise AssertionError("Board {} does not exist for driver {}".format(board, number))
AssertionError: Board 3 does not exist for driver 3-2

The above exception was the direct cause of the following exception:

Traceback (most recent call last):
  File "c:\users\tanner\appdata\local\programs\python\python37\lib\site-packages\mpf\core\system_wide_device.py", line 17, in device_added_system_wide
    await self._initialize()
  File "c:\users\tanner\appdata\local\programs\python\python37\lib\site-packages\mpf\devices\driver.py", line 109, in _initialize
    raise AssertionError("Failed to configure driver {} in platform. See error above".format(self.name)) from e
AssertionError: Failed to configure driver c_flipper_right in platform. See error above
2022-10-11 22:45:24,651 : ERROR : asyncio : Task exception was never retrieved
future: <Task finished coro=<SystemWideDevice.device_added_system_wide() done, defined at c:\users\tanner\appdata\local\programs\python\python37\lib\site-packages\mpf\core\system_wide_device.py:15> exception=ConfigFileError('Failed to configure switch s_left_outlane in platform. See error above')>
Traceback (most recent call last):
  File "c:\users\tanner\appdata\local\programs\python\python37\lib\site-packages\mpf\devices\switch.py", line 149, in _initialize
    self.config['number'], config, self.config['platform_settings'])
  File "c:\users\tanner\appdata\local\programs\python\python37\lib\site-packages\mpf\platforms\fast\fast.py", line 665, in configure_switch
    number = self._parse_switch_number(number)
  File "c:\users\tanner\appdata\local\programs\python\python37\lib\site-packages\mpf\platforms\fast\fast.py", line 597, in _parse_switch_number
    raise AssertionError("Board {} does not exist for switch {}".format(board, number))
AssertionError: Board 3 does not exist for switch 3-2

The above exception was the direct cause of the following exception:

Traceback (most recent call last):
  File "c:\users\tanner\appdata\local\programs\python\python37\lib\site-packages\mpf\core\system_wide_device.py", line 17, in device_added_system_wide
    await self._initialize()
  File "c:\users\tanner\appdata\local\programs\python\python37\lib\site-packages\mpf\devices\switch.py", line 152, in _initialize
    self.class_label) from e
mpf.exceptions.config_file_error.ConfigFileError: Config File Error in switch: Failed to configure switch s_left_outlane in platform. See error above Error Code: CFE-switch-2 (https://docs.missionpinball.org/en/0.55/logs/CFE-switch-2.html)
2022-10-11 22:45:24,651 : ERROR : asyncio : Task exception was never retrieved
future: <Task finished coro=<SystemWideDevice.device_added_system_wide() done, defined at c:\users\tanner\appdata\local\programs\python\python37\lib\site-packages\mpf\core\system_wide_device.py:15> exception=AssertionError('Failed to configure driver c_drop_mid_knockdown in platform. See error above')>
Traceback (most recent call last):
  File "c:\users\tanner\appdata\local\programs\python\python37\lib\site-packages\mpf\devices\driver.py", line 107, in _initialize
    self.hw_driver = self.platform.configure_driver(config, self.config['number'], platform_settings)
  File "c:\users\tanner\appdata\local\programs\python\python37\lib\site-packages\mpf\platforms\fast\fast.py", line 533, in configure_driver
    number = self._parse_driver_number(number)
  File "c:\users\tanner\appdata\local\programs\python\python37\lib\site-packages\mpf\platforms\fast\fast.py", line 481, in _parse_driver_number
    raise AssertionError("Board {} does not exist for driver {}".format(board, number))
AssertionError: Board 2 does not exist for driver 2-8

The above exception was the direct cause of the following exception:

Traceback (most recent call last):
  File "c:\users\tanner\appdata\local\programs\python\python37\lib\site-packages\mpf\core\system_wide_device.py", line 17, in device_added_system_wide
    await self._initialize()
  File "c:\users\tanner\appdata\local\programs\python\python37\lib\site-packages\mpf\devices\driver.py", line 109, in _initialize
    raise AssertionError("Failed to configure driver {} in platform. See error above".format(self.name)) from e
AssertionError: Failed to configure driver c_drop_mid_knockdown in platform. See error above
2022-10-11 22:45:24,651 : ERROR : asyncio : Task exception was never retrieved
future: <Task finished coro=<SystemWideDevice.device_added_system_wide() done, defined at c:\users\tanner\appdata\local\programs\python\python37\lib\site-packages\mpf\core\system_wide_device.py:15> exception=ConfigFileError('Failed to configure switch s_drop_right_right in platform. See error above')>
Traceback (most recent call last):
  File "c:\users\tanner\appdata\local\programs\python\python37\lib\site-packages\mpf\devices\switch.py", line 149, in _initialize
    self.config['number'], config, self.config['platform_settings'])
  File "c:\users\tanner\appdata\local\programs\python\python37\lib\site-packages\mpf\platforms\fast\fast.py", line 665, in configure_switch
    number = self._parse_switch_number(number)
  File "c:\users\tanner\appdata\local\programs\python\python37\lib\site-packages\mpf\platforms\fast\fast.py", line 597, in _parse_switch_number
    raise AssertionError("Board {} does not exist for switch {}".format(board, number))
AssertionError: Board 2 does not exist for switch 2-8

The above exception was the direct cause of the following exception:

Traceback (most recent call last):
  File "c:\users\tanner\appdata\local\programs\python\python37\lib\site-packages\mpf\core\system_wide_device.py", line 17, in device_added_system_wide
    await self._initialize()
  File "c:\users\tanner\appdata\local\programs\python\python37\lib\site-packages\mpf\devices\switch.py", line 152, in _initialize
    self.class_label) from e
mpf.exceptions.config_file_error.ConfigFileError: Config File Error in switch: Failed to configure switch s_drop_right_right in platform. See error above Error Code: CFE-switch-2 (https://docs.missionpinball.org/en/0.55/logs/CFE-switch-2.html)
2022-10-11 22:45:24,652 : ERROR : asyncio : Task exception was never retrieved
future: <Task finished coro=<SystemWideDevice.device_added_system_wide() done, defined at c:\users\tanner\appdata\local\programs\python\python37\lib\site-packages\mpf\core\system_wide_device.py:15> exception=AssertionError('Failed to configure driver c_pop_right in platform. See error above')>
Traceback (most recent call last):
  File "c:\users\tanner\appdata\local\programs\python\python37\lib\site-packages\mpf\devices\driver.py", line 107, in _initialize
    self.hw_driver = self.platform.configure_driver(config, self.config['number'], platform_settings)
  File "c:\users\tanner\appdata\local\programs\python\python37\lib\site-packages\mpf\platforms\fast\fast.py", line 533, in configure_driver
    number = self._parse_driver_number(number)
  File "c:\users\tanner\appdata\local\programs\python\python37\lib\site-packages\mpf\platforms\fast\fast.py", line 481, in _parse_driver_number
    raise AssertionError("Board {} does not exist for driver {}".format(board, number))
AssertionError: Board 2 does not exist for driver 2-9

The above exception was the direct cause of the following exception:

Traceback (most recent call last):
  File "c:\users\tanner\appdata\local\programs\python\python37\lib\site-packages\mpf\core\system_wide_device.py", line 17, in device_added_system_wide
    await self._initialize()
  File "c:\users\tanner\appdata\local\programs\python\python37\lib\site-packages\mpf\devices\driver.py", line 109, in _initialize
    raise AssertionError("Failed to configure driver {} in platform. See error above".format(self.name)) from e
AssertionError: Failed to configure driver c_pop_right in platform. See error above
2022-10-11 22:45:24,652 : ERROR : asyncio : Task exception was never retrieved
future: <Task finished coro=<SystemWideDevice.device_added_system_wide() done, defined at c:\users\tanner\appdata\local\programs\python\python37\lib\site-packages\mpf\core\system_wide_device.py:15> exception=ConfigFileError('Failed to configure switch s_start in platform. See error above')>
Traceback (most recent call last):
  File "c:\users\tanner\appdata\local\programs\python\python37\lib\site-packages\mpf\devices\switch.py", line 149, in _initialize
    self.config['number'], config, self.config['platform_settings'])
  File "c:\users\tanner\appdata\local\programs\python\python37\lib\site-packages\mpf\platforms\fast\fast.py", line 665, in configure_switch
    number = self._parse_switch_number(number)
  File "c:\users\tanner\appdata\local\programs\python\python37\lib\site-packages\mpf\platforms\fast\fast.py", line 597, in _parse_switch_number
    raise AssertionError("Board {} does not exist for switch {}".format(board, number))
AssertionError: Board 0 does not exist for switch 0-2

The above exception was the direct cause of the following exception:

Traceback (most recent call last):
  File "c:\users\tanner\appdata\local\programs\python\python37\lib\site-packages\mpf\core\system_wide_device.py", line 17, in device_added_system_wide
    await self._initialize()
  File "c:\users\tanner\appdata\local\programs\python\python37\lib\site-packages\mpf\devices\switch.py", line 152, in _initialize
    self.class_label) from e
mpf.exceptions.config_file_error.ConfigFileError: Config File Error in switch: Failed to configure switch s_start in platform. See error above Error Code: CFE-switch-2 (https://docs.missionpinball.org/en/0.55/logs/CFE-switch-2.html)
2022-10-11 22:45:24,652 : ERROR : asyncio : Task exception was never retrieved
future: <Task finished coro=<SystemWideDevice.device_added_system_wide() done, defined at c:\users\tanner\appdata\local\programs\python\python37\lib\site-packages\mpf\core\system_wide_device.py:15> exception=ConfigFileError('Failed to configure switch s_back_stationary in platform. See error above')>
Traceback (most recent call last):
  File "c:\users\tanner\appdata\local\programs\python\python37\lib\site-packages\mpf\devices\switch.py", line 149, in _initialize
    self.config['number'], config, self.config['platform_settings'])
  File "c:\users\tanner\appdata\local\programs\python\python37\lib\site-packages\mpf\platforms\fast\fast.py", line 665, in configure_switch
    number = self._parse_switch_number(number)
  File "c:\users\tanner\appdata\local\programs\python\python37\lib\site-packages\mpf\platforms\fast\fast.py", line 597, in _parse_switch_number
    raise AssertionError("Board {} does not exist for switch {}".format(board, number))
AssertionError: Board 1 does not exist for switch 1-6

The above exception was the direct cause of the following exception:

Traceback (most recent call last):
  File "c:\users\tanner\appdata\local\programs\python\python37\lib\site-packages\mpf\core\system_wide_device.py", line 17, in device_added_system_wide
    await self._initialize()
  File "c:\users\tanner\appdata\local\programs\python\python37\lib\site-packages\mpf\devices\switch.py", line 152, in _initialize
    self.class_label) from e
mpf.exceptions.config_file_error.ConfigFileError: Config File Error in switch: Failed to configure switch s_back_stationary in platform. See error above Error Code: CFE-switch-2 (https://docs.missionpinball.org/en/0.55/logs/CFE-switch-2.html)
2022-10-11 22:45:24,653 : ERROR : asyncio : Task exception was never retrieved
future: <Task finished coro=<SystemWideDevice.device_added_system_wide() done, defined at c:\users\tanner\appdata\local\programs\python\python37\lib\site-packages\mpf\core\system_wide_device.py:15> exception=AssertionError('Failed to configure driver c_flipper_right_hold in platform. See error above')>
Traceback (most recent call last):
  File "c:\users\tanner\appdata\local\programs\python\python37\lib\site-packages\mpf\devices\driver.py", line 107, in _initialize
    self.hw_driver = self.platform.configure_driver(config, self.config['number'], platform_settings)
  File "c:\users\tanner\appdata\local\programs\python\python37\lib\site-packages\mpf\platforms\fast\fast.py", line 533, in configure_driver
    number = self._parse_driver_number(number)
  File "c:\users\tanner\appdata\local\programs\python\python37\lib\site-packages\mpf\platforms\fast\fast.py", line 481, in _parse_driver_number
    raise AssertionError("Board {} does not exist for driver {}".format(board, number))
AssertionError: Board 3 does not exist for driver 3-3

The above exception was the direct cause of the following exception:

Traceback (most recent call last):
  File "c:\users\tanner\appdata\local\programs\python\python37\lib\site-packages\mpf\core\system_wide_device.py", line 17, in device_added_system_wide
    await self._initialize()
  File "c:\users\tanner\appdata\local\programs\python\python37\lib\site-packages\mpf\devices\driver.py", line 109, in _initialize
    raise AssertionError("Failed to configure driver {} in platform. See error above".format(self.name)) from e
AssertionError: Failed to configure driver c_flipper_right_hold in platform. See error above
2022-10-11 22:45:24,653 : ERROR : asyncio : Task exception was never retrieved
future: <Task finished coro=<SystemWideDevice.device_added_system_wide() done, defined at c:\users\tanner\appdata\local\programs\python\python37\lib\site-packages\mpf\core\system_wide_device.py:15> exception=AssertionError('Failed to configure driver c_drop_single in platform. See error above')>
Traceback (most recent call last):
  File "c:\users\tanner\appdata\local\programs\python\python37\lib\site-packages\mpf\devices\driver.py", line 107, in _initialize
    self.hw_driver = self.platform.configure_driver(config, self.config['number'], platform_settings)
  File "c:\users\tanner\appdata\local\programs\python\python37\lib\site-packages\mpf\platforms\fast\fast.py", line 533, in configure_driver
    number = self._parse_driver_number(number)
  File "c:\users\tanner\appdata\local\programs\python\python37\lib\site-packages\mpf\platforms\fast\fast.py", line 481, in _parse_driver_number
    raise AssertionError("Board {} does not exist for driver {}".format(board, number))
AssertionError: Board 2 does not exist for driver 2-11

The above exception was the direct cause of the following exception:

Traceback (most recent call last):
  File "c:\users\tanner\appdata\local\programs\python\python37\lib\site-packages\mpf\core\system_wide_device.py", line 17, in device_added_system_wide
    await self._initialize()
  File "c:\users\tanner\appdata\local\programs\python\python37\lib\site-packages\mpf\devices\driver.py", line 109, in _initialize
    raise AssertionError("Failed to configure driver {} in platform. See error above".format(self.name)) from e
AssertionError: Failed to configure driver c_drop_single in platform. See error above
2022-10-11 22:45:24,653 : ERROR : asyncio : Task exception was never retrieved
future: <Task finished coro=<SystemWideDevice.device_added_system_wide() done, defined at c:\users\tanner\appdata\local\programs\python\python37\lib\site-packages\mpf\core\system_wide_device.py:15> exception=ConfigFileError('Failed to configure switch s_trough_jam in platform. See error above')>
Traceback (most recent call last):
  File "c:\users\tanner\appdata\local\programs\python\python37\lib\site-packages\mpf\devices\switch.py", line 149, in _initialize
    self.config['number'], config, self.config['platform_settings'])
  File "c:\users\tanner\appdata\local\programs\python\python37\lib\site-packages\mpf\platforms\fast\fast.py", line 665, in configure_switch
    number = self._parse_switch_number(number)
  File "c:\users\tanner\appdata\local\programs\python\python37\lib\site-packages\mpf\platforms\fast\fast.py", line 597, in _parse_switch_number
    raise AssertionError("Board {} does not exist for switch {}".format(board, number))
AssertionError: Board 3 does not exist for switch 3-17

The above exception was the direct cause of the following exception:

Traceback (most recent call last):
  File "c:\users\tanner\appdata\local\programs\python\python37\lib\site-packages\mpf\core\system_wide_device.py", line 17, in device_added_system_wide
    await self._initialize()
  File "c:\users\tanner\appdata\local\programs\python\python37\lib\site-packages\mpf\devices\switch.py", line 152, in _initialize
    self.class_label) from e
mpf.exceptions.config_file_error.ConfigFileError: Config File Error in switch: Failed to configure switch s_trough_jam in platform. See error above Error Code: CFE-switch-2 (https://docs.missionpinball.org/en/0.55/logs/CFE-switch-2.html)
2022-10-11 22:45:24,654 : ERROR : asyncio : Task exception was never retrieved
future: <Task finished coro=<SystemWideDevice.device_added_system_wide() done, defined at c:\users\tanner\appdata\local\programs\python\python37\lib\site-packages\mpf\core\system_wide_device.py:15> exception=ConfigFileError('Failed to configure switch s_left_inlane in platform. See error above')>
Traceback (most recent call last):
  File "c:\users\tanner\appdata\local\programs\python\python37\lib\site-packages\mpf\devices\switch.py", line 149, in _initialize
    self.config['number'], config, self.config['platform_settings'])
  File "c:\users\tanner\appdata\local\programs\python\python37\lib\site-packages\mpf\platforms\fast\fast.py", line 665, in configure_switch
    number = self._parse_switch_number(number)
  File "c:\users\tanner\appdata\local\programs\python\python37\lib\site-packages\mpf\platforms\fast\fast.py", line 597, in _parse_switch_number
    raise AssertionError("Board {} does not exist for switch {}".format(board, number))
AssertionError: Board 3 does not exist for switch 3-1

The above exception was the direct cause of the following exception:

Traceback (most recent call last):
  File "c:\users\tanner\appdata\local\programs\python\python37\lib\site-packages\mpf\core\system_wide_device.py", line 17, in device_added_system_wide
    await self._initialize()
  File "c:\users\tanner\appdata\local\programs\python\python37\lib\site-packages\mpf\devices\switch.py", line 152, in _initialize
    self.class_label) from e
mpf.exceptions.config_file_error.ConfigFileError: Config File Error in switch: Failed to configure switch s_left_inlane in platform. See error above Error Code: CFE-switch-2 (https://docs.missionpinball.org/en/0.55/logs/CFE-switch-2.html)
2022-10-11 22:45:24,654 : ERROR : asyncio : Task exception was never retrieved
future: <Task finished coro=<SystemWideDevice.device_added_system_wide() done, defined at c:\users\tanner\appdata\local\programs\python\python37\lib\site-packages\mpf\core\system_wide_device.py:15> exception=ConfigFileError('Failed to configure switch s_drop_right_left in platform. See error above')>
Traceback (most recent call last):
  File "c:\users\tanner\appdata\local\programs\python\python37\lib\site-packages\mpf\devices\switch.py", line 149, in _initialize
    self.config['number'], config, self.config['platform_settings'])
  File "c:\users\tanner\appdata\local\programs\python\python37\lib\site-packages\mpf\platforms\fast\fast.py", line 665, in configure_switch
    number = self._parse_switch_number(number)
  File "c:\users\tanner\appdata\local\programs\python\python37\lib\site-packages\mpf\platforms\fast\fast.py", line 597, in _parse_switch_number
    raise AssertionError("Board {} does not exist for switch {}".format(board, number))
AssertionError: Board 2 does not exist for switch 2-9

The above exception was the direct cause of the following exception:

Traceback (most recent call last):
  File "c:\users\tanner\appdata\local\programs\python\python37\lib\site-packages\mpf\core\system_wide_device.py", line 17, in device_added_system_wide
    await self._initialize()
  File "c:\users\tanner\appdata\local\programs\python\python37\lib\site-packages\mpf\devices\switch.py", line 152, in _initialize
    self.class_label) from e
mpf.exceptions.config_file_error.ConfigFileError: Config File Error in switch: Failed to configure switch s_drop_right_left in platform. See error above Error Code: CFE-switch-2 (https://docs.missionpinball.org/en/0.55/logs/CFE-switch-2.html)
2022-10-11 22:45:24,654 : ERROR : asyncio : Task exception was never retrieved
future: <Task finished coro=<SystemWideDevice.device_added_system_wide() done, defined at c:\users\tanner\appdata\local\programs\python\python37\lib\site-packages\mpf\core\system_wide_device.py:15> exception=AssertionError('Failed to configure driver c_pop_lower in platform. See error above')>
Traceback (most recent call last):
  File "c:\users\tanner\appdata\local\programs\python\python37\lib\site-packages\mpf\devices\driver.py", line 107, in _initialize
    self.hw_driver = self.platform.configure_driver(config, self.config['number'], platform_settings)
  File "c:\users\tanner\appdata\local\programs\python\python37\lib\site-packages\mpf\platforms\fast\fast.py", line 533, in configure_driver
    number = self._parse_driver_number(number)
  File "c:\users\tanner\appdata\local\programs\python\python37\lib\site-packages\mpf\platforms\fast\fast.py", line 481, in _parse_driver_number
    raise AssertionError("Board {} does not exist for driver {}".format(board, number))
AssertionError: Board 2 does not exist for driver 2-0

The above exception was the direct cause of the following exception:

Traceback (most recent call last):
  File "c:\users\tanner\appdata\local\programs\python\python37\lib\site-packages\mpf\core\system_wide_device.py", line 17, in device_added_system_wide
    await self._initialize()
  File "c:\users\tanner\appdata\local\programs\python\python37\lib\site-packages\mpf\devices\driver.py", line 109, in _initialize
    raise AssertionError("Failed to configure driver {} in platform. See error above".format(self.name)) from e
AssertionError: Failed to configure driver c_pop_lower in platform. See error above
2022-10-11 22:45:24,655 : ERROR : asyncio : Task exception was never retrieved
future: <Task finished coro=<SystemWideDevice.device_added_system_wide() done, defined at c:\users\tanner\appdata\local\programs\python\python37\lib\site-packages\mpf\core\system_wide_device.py:15> exception=ConfigFileError('Failed to configure switch s_transfer_rollover in platform. See error above')>
Traceback (most recent call last):
  File "c:\users\tanner\appdata\local\programs\python\python37\lib\site-packages\mpf\devices\switch.py", line 149, in _initialize
    self.config['number'], config, self.config['platform_settings'])
  File "c:\users\tanner\appdata\local\programs\python\python37\lib\site-packages\mpf\platforms\fast\fast.py", line 665, in configure_switch
    number = self._parse_switch_number(number)
  File "c:\users\tanner\appdata\local\programs\python\python37\lib\site-packages\mpf\platforms\fast\fast.py", line 597, in _parse_switch_number
    raise AssertionError("Board {} does not exist for switch {}".format(board, number))
AssertionError: Board 1 does not exist for switch 1-5

The above exception was the direct cause of the following exception:

Traceback (most recent call last):
  File "c:\users\tanner\appdata\local\programs\python\python37\lib\site-packages\mpf\core\system_wide_device.py", line 17, in device_added_system_wide
    await self._initialize()
  File "c:\users\tanner\appdata\local\programs\python\python37\lib\site-packages\mpf\devices\switch.py", line 152, in _initialize
    self.class_label) from e
mpf.exceptions.config_file_error.ConfigFileError: Config File Error in switch: Failed to configure switch s_transfer_rollover in platform. See error above Error Code: CFE-switch-2 (https://docs.missionpinball.org/en/0.55/logs/CFE-switch-2.html)
2022-10-11 22:45:24,655 : ERROR : asyncio : Task exception was never retrieved
future: <Task finished coro=<SystemWideDevice.device_added_system_wide() done, defined at c:\users\tanner\appdata\local\programs\python\python37\lib\site-packages\mpf\core\system_wide_device.py:15> exception=AssertionError('Failed to configure driver c_flipper_left_top in platform. See error above')>
Traceback (most recent call last):
  File "c:\users\tanner\appdata\local\programs\python\python37\lib\site-packages\mpf\devices\driver.py", line 107, in _initialize
    self.hw_driver = self.platform.configure_driver(config, self.config['number'], platform_settings)
  File "c:\users\tanner\appdata\local\programs\python\python37\lib\site-packages\mpf\platforms\fast\fast.py", line 533, in configure_driver
    number = self._parse_driver_number(number)
  File "c:\users\tanner\appdata\local\programs\python\python37\lib\site-packages\mpf\platforms\fast\fast.py", line 481, in _parse_driver_number
    raise AssertionError("Board {} does not exist for driver {}".format(board, number))
AssertionError: Board 3 does not exist for driver 3-6

The above exception was the direct cause of the following exception:

Traceback (most recent call last):
  File "c:\users\tanner\appdata\local\programs\python\python37\lib\site-packages\mpf\core\system_wide_device.py", line 17, in device_added_system_wide
    await self._initialize()
  File "c:\users\tanner\appdata\local\programs\python\python37\lib\site-packages\mpf\devices\driver.py", line 109, in _initialize
    raise AssertionError("Failed to configure driver {} in platform. See error above".format(self.name)) from e
AssertionError: Failed to configure driver c_flipper_left_top in platform. See error above
2022-10-11 22:45:24,655 : ERROR : asyncio : Task exception was never retrieved
future: <Task finished coro=<SystemWideDevice.device_added_system_wide() done, defined at c:\users\tanner\appdata\local\programs\python\python37\lib\site-packages\mpf\core\system_wide_device.py:15> exception=ConfigFileError('Failed to configure switch s_launch in platform. See error above')>
Traceback (most recent call last):
  File "c:\users\tanner\appdata\local\programs\python\python37\lib\site-packages\mpf\devices\switch.py", line 149, in _initialize
    self.config['number'], config, self.config['platform_settings'])
  File "c:\users\tanner\appdata\local\programs\python\python37\lib\site-packages\mpf\platforms\fast\fast.py", line 665, in configure_switch
    number = self._parse_switch_number(number)
  File "c:\users\tanner\appdata\local\programs\python\python37\lib\site-packages\mpf\platforms\fast\fast.py", line 597, in _parse_switch_number
    raise AssertionError("Board {} does not exist for switch {}".format(board, number))
AssertionError: Board 0 does not exist for switch 0-1

The above exception was the direct cause of the following exception:

Traceback (most recent call last):
  File "c:\users\tanner\appdata\local\programs\python\python37\lib\site-packages\mpf\core\system_wide_device.py", line 17, in device_added_system_wide
    await self._initialize()
  File "c:\users\tanner\appdata\local\programs\python\python37\lib\site-packages\mpf\devices\switch.py", line 152, in _initialize
    self.class_label) from e
mpf.exceptions.config_file_error.ConfigFileError: Config File Error in switch: Failed to configure switch s_launch in platform. See error above Error Code: CFE-switch-2 (https://docs.missionpinball.org/en/0.55/logs/CFE-switch-2.html)
2022-10-11 22:45:24,656 : ERROR : asyncio : Task exception was never retrieved
future: <Task finished coro=<SystemWideDevice.device_added_system_wide() done, defined at c:\users\tanner\appdata\local\programs\python\python37\lib\site-packages\mpf\core\system_wide_device.py:15> exception=ConfigFileError('Failed to configure switch s_bot_big in platform. See error above')>
Traceback (most recent call last):
  File "c:\users\tanner\appdata\local\programs\python\python37\lib\site-packages\mpf\devices\switch.py", line 149, in _initialize
    self.config['number'], config, self.config['platform_settings'])
  File "c:\users\tanner\appdata\local\programs\python\python37\lib\site-packages\mpf\platforms\fast\fast.py", line 665, in configure_switch
    number = self._parse_switch_number(number)
  File "c:\users\tanner\appdata\local\programs\python\python37\lib\site-packages\mpf\platforms\fast\fast.py", line 597, in _parse_switch_number
    raise AssertionError("Board {} does not exist for switch {}".format(board, number))
AssertionError: Board 4 does not exist for switch 4-3

The above exception was the direct cause of the following exception:

Traceback (most recent call last):
  File "c:\users\tanner\appdata\local\programs\python\python37\lib\site-packages\mpf\core\system_wide_device.py", line 17, in device_added_system_wide
    await self._initialize()
  File "c:\users\tanner\appdata\local\programs\python\python37\lib\site-packages\mpf\devices\switch.py", line 152, in _initialize
    self.class_label) from e
mpf.exceptions.config_file_error.ConfigFileError: Config File Error in switch: Failed to configure switch s_bot_big in platform. See error above Error Code: CFE-switch-2 (https://docs.missionpinball.org/en/0.55/logs/CFE-switch-2.html)
2022-10-11 22:45:24,656 : ERROR : asyncio : Task exception was never retrieved
future: <Task finished coro=<SystemWideDevice.device_added_system_wide() done, defined at c:\users\tanner\appdata\local\programs\python\python37\lib\site-packages\mpf\core\system_wide_device.py:15> exception=AssertionError('Failed to configure driver c_drop_single_knockdown in platform. See error above')>
Traceback (most recent call last):
  File "c:\users\tanner\appdata\local\programs\python\python37\lib\site-packages\mpf\devices\driver.py", line 107, in _initialize
    self.hw_driver = self.platform.configure_driver(config, self.config['number'], platform_settings)
  File "c:\users\tanner\appdata\local\programs\python\python37\lib\site-packages\mpf\platforms\fast\fast.py", line 533, in configure_driver
    number = self._parse_driver_number(number)
  File "c:\users\tanner\appdata\local\programs\python\python37\lib\site-packages\mpf\platforms\fast\fast.py", line 481, in _parse_driver_number
    raise AssertionError("Board {} does not exist for driver {}".format(board, number))
AssertionError: Board 2 does not exist for driver 2-12

The above exception was the direct cause of the following exception:

Traceback (most recent call last):
  File "c:\users\tanner\appdata\local\programs\python\python37\lib\site-packages\mpf\core\system_wide_device.py", line 17, in device_added_system_wide
    await self._initialize()
  File "c:\users\tanner\appdata\local\programs\python\python37\lib\site-packages\mpf\devices\driver.py", line 109, in _initialize
    raise AssertionError("Failed to configure driver {} in platform. See error above".format(self.name)) from e
AssertionError: Failed to configure driver c_drop_single_knockdown in platform. See error above
2022-10-11 22:45:24,656 : ERROR : asyncio : Task exception was never retrieved
future: <Task finished coro=<SystemWideDevice.device_added_system_wide() done, defined at c:\users\tanner\appdata\local\programs\python\python37\lib\site-packages\mpf\core\system_wide_device.py:15> exception=ConfigFileError('Failed to configure switch s_autolauncher in platform. See error above')>
Traceback (most recent call last):
  File "c:\users\tanner\appdata\local\programs\python\python37\lib\site-packages\mpf\devices\switch.py", line 149, in _initialize
    self.config['number'], config, self.config['platform_settings'])
  File "c:\users\tanner\appdata\local\programs\python\python37\lib\site-packages\mpf\platforms\fast\fast.py", line 665, in configure_switch
    number = self._parse_switch_number(number)
  File "c:\users\tanner\appdata\local\programs\python\python37\lib\site-packages\mpf\platforms\fast\fast.py", line 597, in _parse_switch_number
    raise AssertionError("Board {} does not exist for switch {}".format(board, number))
AssertionError: Board 3 does not exist for switch 3-7

The above exception was the direct cause of the following exception:

Traceback (most recent call last):
  File "c:\users\tanner\appdata\local\programs\python\python37\lib\site-packages\mpf\core\system_wide_device.py", line 17, in device_added_system_wide
    await self._initialize()
  File "c:\users\tanner\appdata\local\programs\python\python37\lib\site-packages\mpf\devices\switch.py", line 152, in _initialize
    self.class_label) from e
mpf.exceptions.config_file_error.ConfigFileError: Config File Error in switch: Failed to configure switch s_autolauncher in platform. See error above Error Code: CFE-switch-2 (https://docs.missionpinball.org/en/0.55/logs/CFE-switch-2.html)
2022-10-11 22:45:24,657 : ERROR : asyncio : Task exception was never retrieved
future: <Task finished coro=<SystemWideDevice.device_added_system_wide() done, defined at c:\users\tanner\appdata\local\programs\python\python37\lib\site-packages\mpf\core\system_wide_device.py:15> exception=ConfigFileError('Failed to configure switch s_rollover_left in platform. See error above')>
Traceback (most recent call last):
  File "c:\users\tanner\appdata\local\programs\python\python37\lib\site-packages\mpf\devices\switch.py", line 149, in _initialize
    self.config['number'], config, self.config['platform_settings'])
  File "c:\users\tanner\appdata\local\programs\python\python37\lib\site-packages\mpf\platforms\fast\fast.py", line 665, in configure_switch
    number = self._parse_switch_number(number)
  File "c:\users\tanner\appdata\local\programs\python\python37\lib\site-packages\mpf\platforms\fast\fast.py", line 597, in _parse_switch_number
    raise AssertionError("Board {} does not exist for switch {}".format(board, number))
AssertionError: Board 2 does not exist for switch 2-13

The above exception was the direct cause of the following exception:

Traceback (most recent call last):
  File "c:\users\tanner\appdata\local\programs\python\python37\lib\site-packages\mpf\core\system_wide_device.py", line 17, in device_added_system_wide
    await self._initialize()
  File "c:\users\tanner\appdata\local\programs\python\python37\lib\site-packages\mpf\devices\switch.py", line 152, in _initialize
    self.class_label) from e
mpf.exceptions.config_file_error.ConfigFileError: Config File Error in switch: Failed to configure switch s_rollover_left in platform. See error above Error Code: CFE-switch-2 (https://docs.missionpinball.org/en/0.55/logs/CFE-switch-2.html)
2022-10-11 22:45:24,657 : ERROR : asyncio : Task exception was never retrieved
future: <Task finished coro=<SystemWideDevice.device_added_system_wide() done, defined at c:\users\tanner\appdata\local\programs\python\python37\lib\site-packages\mpf\core\system_wide_device.py:15> exception=AssertionError('Failed to configure driver c_top_vuk in platform. See error above')>
Traceback (most recent call last):
  File "c:\users\tanner\appdata\local\programs\python\python37\lib\site-packages\mpf\devices\driver.py", line 107, in _initialize
    self.hw_driver = self.platform.configure_driver(config, self.config['number'], platform_settings)
  File "c:\users\tanner\appdata\local\programs\python\python37\lib\site-packages\mpf\platforms\fast\fast.py", line 533, in configure_driver
    number = self._parse_driver_number(number)
  File "c:\users\tanner\appdata\local\programs\python\python37\lib\site-packages\mpf\platforms\fast\fast.py", line 481, in _parse_driver_number
    raise AssertionError("Board {} does not exist for driver {}".format(board, number))
AssertionError: Board 2 does not exist for driver 2-10

The above exception was the direct cause of the following exception:

Traceback (most recent call last):
  File "c:\users\tanner\appdata\local\programs\python\python37\lib\site-packages\mpf\core\system_wide_device.py", line 17, in device_added_system_wide
    await self._initialize()
  File "c:\users\tanner\appdata\local\programs\python\python37\lib\site-packages\mpf\devices\driver.py", line 109, in _initialize
    raise AssertionError("Failed to configure driver {} in platform. See error above".format(self.name)) from e
AssertionError: Failed to configure driver c_top_vuk in platform. See error above
2022-10-11 22:45:24,657 : ERROR : asyncio : Task exception was never retrieved
future: <Task finished coro=<SystemWideDevice.device_added_system_wide() done, defined at c:\users\tanner\appdata\local\programs\python\python37\lib\site-packages\mpf\core\system_wide_device.py:15> exception=ConfigFileError('Failed to configure switch s_pop_lower in platform. See error above')>
Traceback (most recent call last):
  File "c:\users\tanner\appdata\local\programs\python\python37\lib\site-packages\mpf\devices\switch.py", line 149, in _initialize
    self.config['number'], config, self.config['platform_settings'])
  File "c:\users\tanner\appdata\local\programs\python\python37\lib\site-packages\mpf\platforms\fast\fast.py", line 665, in configure_switch
    number = self._parse_switch_number(number)
  File "c:\users\tanner\appdata\local\programs\python\python37\lib\site-packages\mpf\platforms\fast\fast.py", line 597, in _parse_switch_number
    raise AssertionError("Board {} does not exist for switch {}".format(board, number))
AssertionError: Board 2 does not exist for switch 2-0

The above exception was the direct cause of the following exception:

Traceback (most recent call last):
  File "c:\users\tanner\appdata\local\programs\python\python37\lib\site-packages\mpf\core\system_wide_device.py", line 17, in device_added_system_wide
    await self._initialize()
  File "c:\users\tanner\appdata\local\programs\python\python37\lib\site-packages\mpf\devices\switch.py", line 152, in _initialize
    self.class_label) from e
mpf.exceptions.config_file_error.ConfigFileError: Config File Error in switch: Failed to configure switch s_pop_lower in platform. See error above Error Code: CFE-switch-2 (https://docs.missionpinball.org/en/0.55/logs/CFE-switch-2.html)
2022-10-11 22:45:24,658 : ERROR : asyncio : Task exception was never retrieved
future: <Task finished coro=<SystemWideDevice.device_added_system_wide() done, defined at c:\users\tanner\appdata\local\programs\python\python37\lib\site-packages\mpf\core\system_wide_device.py:15> exception=AssertionError('Failed to configure driver c_flipper_left_top_hold in platform. See error above')>
Traceback (most recent call last):
  File "c:\users\tanner\appdata\local\programs\python\python37\lib\site-packages\mpf\devices\driver.py", line 107, in _initialize
    self.hw_driver = self.platform.configure_driver(config, self.config['number'], platform_settings)
  File "c:\users\tanner\appdata\local\programs\python\python37\lib\site-packages\mpf\platforms\fast\fast.py", line 533, in configure_driver
    number = self._parse_driver_number(number)
  File "c:\users\tanner\appdata\local\programs\python\python37\lib\site-packages\mpf\platforms\fast\fast.py", line 481, in _parse_driver_number
    raise AssertionError("Board {} does not exist for driver {}".format(board, number))
AssertionError: Board 3 does not exist for driver 3-7

The above exception was the direct cause of the following exception:

Traceback (most recent call last):
  File "c:\users\tanner\appdata\local\programs\python\python37\lib\site-packages\mpf\core\system_wide_device.py", line 17, in device_added_system_wide
    await self._initialize()
  File "c:\users\tanner\appdata\local\programs\python\python37\lib\site-packages\mpf\devices\driver.py", line 109, in _initialize
    raise AssertionError("Failed to configure driver {} in platform. See error above".format(self.name)) from e
AssertionError: Failed to configure driver c_flipper_left_top_hold in platform. See error above
2022-10-11 22:45:24,659 : ERROR : asyncio : Task exception was never retrieved
future: <Task finished coro=<SystemWideDevice.device_added_system_wide() done, defined at c:\users\tanner\appdata\local\programs\python\python37\lib\site-packages\mpf\core\system_wide_device.py:15> exception=ConfigFileError('Failed to configure switch s_tilt in platform. See error above')>
Traceback (most recent call last):
  File "c:\users\tanner\appdata\local\programs\python\python37\lib\site-packages\mpf\devices\switch.py", line 149, in _initialize
    self.config['number'], config, self.config['platform_settings'])
  File "c:\users\tanner\appdata\local\programs\python\python37\lib\site-packages\mpf\platforms\fast\fast.py", line 665, in configure_switch
    number = self._parse_switch_number(number)
  File "c:\users\tanner\appdata\local\programs\python\python37\lib\site-packages\mpf\platforms\fast\fast.py", line 597, in _parse_switch_number
    raise AssertionError("Board {} does not exist for switch {}".format(board, number))
AssertionError: Board 0 does not exist for switch 0-5

The above exception was the direct cause of the following exception:

Traceback (most recent call last):
  File "c:\users\tanner\appdata\local\programs\python\python37\lib\site-packages\mpf\core\system_wide_device.py", line 17, in device_added_system_wide
    await self._initialize()
  File "c:\users\tanner\appdata\local\programs\python\python37\lib\site-packages\mpf\devices\switch.py", line 152, in _initialize
    self.class_label) from e
mpf.exceptions.config_file_error.ConfigFileError: Config File Error in switch: Failed to configure switch s_tilt in platform. See error above Error Code: CFE-switch-2 (https://docs.missionpinball.org/en/0.55/logs/CFE-switch-2.html)
2022-10-11 22:45:24,659 : ERROR : asyncio : Task exception was never retrieved
future: <Task finished coro=<SystemWideDevice.device_added_system_wide() done, defined at c:\users\tanner\appdata\local\programs\python\python37\lib\site-packages\mpf\core\system_wide_device.py:15> exception=ConfigFileError('Failed to configure switch s_bot_left in platform. See error above')>
Traceback (most recent call last):
  File "c:\users\tanner\appdata\local\programs\python\python37\lib\site-packages\mpf\devices\switch.py", line 149, in _initialize
    self.config['number'], config, self.config['platform_settings'])
  File "c:\users\tanner\appdata\local\programs\python\python37\lib\site-packages\mpf\platforms\fast\fast.py", line 665, in configure_switch
    number = self._parse_switch_number(number)
  File "c:\users\tanner\appdata\local\programs\python\python37\lib\site-packages\mpf\platforms\fast\fast.py", line 597, in _parse_switch_number
    raise AssertionError("Board {} does not exist for switch {}".format(board, number))
AssertionError: Board 4 does not exist for switch 4-1

The above exception was the direct cause of the following exception:

Traceback (most recent call last):
  File "c:\users\tanner\appdata\local\programs\python\python37\lib\site-packages\mpf\core\system_wide_device.py", line 17, in device_added_system_wide
    await self._initialize()
  File "c:\users\tanner\appdata\local\programs\python\python37\lib\site-packages\mpf\devices\switch.py", line 152, in _initialize
    self.class_label) from e
mpf.exceptions.config_file_error.ConfigFileError: Config File Error in switch: Failed to configure switch s_bot_left in platform. See error above Error Code: CFE-switch-2 (https://docs.missionpinball.org/en/0.55/logs/CFE-switch-2.html)
2022-10-11 22:45:24,659 : ERROR : asyncio : Task exception was never retrieved
future: <Task finished coro=<SystemWideDevice.device_added_system_wide() done, defined at c:\users\tanner\appdata\local\programs\python\python37\lib\site-packages\mpf\core\system_wide_device.py:15> exception=AssertionError('Failed to configure driver c_post_inlane in platform. See error above')>
Traceback (most recent call last):
  File "c:\users\tanner\appdata\local\programs\python\python37\lib\site-packages\mpf\devices\driver.py", line 107, in _initialize
    self.hw_driver = self.platform.configure_driver(config, self.config['number'], platform_settings)
  File "c:\users\tanner\appdata\local\programs\python\python37\lib\site-packages\mpf\platforms\fast\fast.py", line 533, in configure_driver
    number = self._parse_driver_number(number)
  File "c:\users\tanner\appdata\local\programs\python\python37\lib\site-packages\mpf\platforms\fast\fast.py", line 481, in _parse_driver_number
    raise AssertionError("Board {} does not exist for driver {}".format(board, number))
AssertionError: Board 2 does not exist for driver 2-1

The above exception was the direct cause of the following exception:

Traceback (most recent call last):
  File "c:\users\tanner\appdata\local\programs\python\python37\lib\site-packages\mpf\core\system_wide_device.py", line 17, in device_added_system_wide
    await self._initialize()
  File "c:\users\tanner\appdata\local\programs\python\python37\lib\site-packages\mpf\devices\driver.py", line 109, in _initialize
    raise AssertionError("Failed to configure driver {} in platform. See error above".format(self.name)) from e
AssertionError: Failed to configure driver c_post_inlane in platform. See error above
2022-10-11 22:45:24,660 : ERROR : asyncio : Task exception was never retrieved
future: <Task finished coro=<SystemWideDevice.device_added_system_wide() done, defined at c:\users\tanner\appdata\local\programs\python\python37\lib\site-packages\mpf\core\system_wide_device.py:15> exception=ConfigFileError('Failed to configure switch s_eos_right in platform. See error above')>
Traceback (most recent call last):
  File "c:\users\tanner\appdata\local\programs\python\python37\lib\site-packages\mpf\devices\switch.py", line 149, in _initialize
    self.config['number'], config, self.config['platform_settings'])
  File "c:\users\tanner\appdata\local\programs\python\python37\lib\site-packages\mpf\platforms\fast\fast.py", line 665, in configure_switch
    number = self._parse_switch_number(number)
  File "c:\users\tanner\appdata\local\programs\python\python37\lib\site-packages\mpf\platforms\fast\fast.py", line 597, in _parse_switch_number
    raise AssertionError("Board {} does not exist for switch {}".format(board, number))
AssertionError: Board 3 does not exist for switch 3-4

The above exception was the direct cause of the following exception:

Traceback (most recent call last):
  File "c:\users\tanner\appdata\local\programs\python\python37\lib\site-packages\mpf\core\system_wide_device.py", line 17, in device_added_system_wide
    await self._initialize()
  File "c:\users\tanner\appdata\local\programs\python\python37\lib\site-packages\mpf\devices\switch.py", line 152, in _initialize
    self.class_label) from e
mpf.exceptions.config_file_error.ConfigFileError: Config File Error in switch: Failed to configure switch s_eos_right in platform. See error above Error Code: CFE-switch-2 (https://docs.missionpinball.org/en/0.55/logs/CFE-switch-2.html)
2022-10-11 22:45:24,660 : ERROR : asyncio : Task exception was never retrieved
future: <Task finished coro=<SystemWideDevice.device_added_system_wide() done, defined at c:\users\tanner\appdata\local\programs\python\python37\lib\site-packages\mpf\core\system_wide_device.py:15> exception=ConfigFileError('Failed to configure switch s_rollover_right in platform. See error above')>
Traceback (most recent call last):
  File "c:\users\tanner\appdata\local\programs\python\python37\lib\site-packages\mpf\devices\switch.py", line 149, in _initialize
    self.config['number'], config, self.config['platform_settings'])
  File "c:\users\tanner\appdata\local\programs\python\python37\lib\site-packages\mpf\platforms\fast\fast.py", line 665, in configure_switch
    number = self._parse_switch_number(number)
  File "c:\users\tanner\appdata\local\programs\python\python37\lib\site-packages\mpf\platforms\fast\fast.py", line 597, in _parse_switch_number
    raise AssertionError("Board {} does not exist for switch {}".format(board, number))
AssertionError: Board 2 does not exist for switch 2-6

The above exception was the direct cause of the following exception:

Traceback (most recent call last):
  File "c:\users\tanner\appdata\local\programs\python\python37\lib\site-packages\mpf\core\system_wide_device.py", line 17, in device_added_system_wide
    await self._initialize()
  File "c:\users\tanner\appdata\local\programs\python\python37\lib\site-packages\mpf\devices\switch.py", line 152, in _initialize
    self.class_label) from e
mpf.exceptions.config_file_error.ConfigFileError: Config File Error in switch: Failed to configure switch s_rollover_right in platform. See error above Error Code: CFE-switch-2 (https://docs.missionpinball.org/en/0.55/logs/CFE-switch-2.html)
2022-10-11 22:45:24,660 : ERROR : asyncio : Task exception was never retrieved
future: <Task finished coro=<SystemWideDevice.device_added_system_wide() done, defined at c:\users\tanner\appdata\local\programs\python\python37\lib\site-packages\mpf\core\system_wide_device.py:15> exception=AssertionError('Failed to configure driver c_right_vuk in platform. See error above')>
Traceback (most recent call last):
  File "c:\users\tanner\appdata\local\programs\python\python37\lib\site-packages\mpf\devices\driver.py", line 107, in _initialize
    self.hw_driver = self.platform.configure_driver(config, self.config['number'], platform_settings)
  File "c:\users\tanner\appdata\local\programs\python\python37\lib\site-packages\mpf\platforms\fast\fast.py", line 533, in configure_driver
    number = self._parse_driver_number(number)
  File "c:\users\tanner\appdata\local\programs\python\python37\lib\site-packages\mpf\platforms\fast\fast.py", line 481, in _parse_driver_number
    raise AssertionError("Board {} does not exist for driver {}".format(board, number))
AssertionError: Board 2 does not exist for driver 2-13

The above exception was the direct cause of the following exception:

Traceback (most recent call last):
  File "c:\users\tanner\appdata\local\programs\python\python37\lib\site-packages\mpf\core\system_wide_device.py", line 17, in device_added_system_wide
    await self._initialize()
  File "c:\users\tanner\appdata\local\programs\python\python37\lib\site-packages\mpf\devices\driver.py", line 109, in _initialize
    raise AssertionError("Failed to configure driver {} in platform. See error above".format(self.name)) from e
AssertionError: Failed to configure driver c_right_vuk in platform. See error above
2022-10-11 22:45:24,661 : ERROR : asyncio : Task exception was never retrieved
future: <Task finished coro=<SystemWideDevice.device_added_system_wide() done, defined at c:\users\tanner\appdata\local\programs\python\python37\lib\site-packages\mpf\core\system_wide_device.py:15> exception=ConfigFileError('Failed to configure switch s_pop_left in platform. See error above')>
Traceback (most recent call last):
  File "c:\users\tanner\appdata\local\programs\python\python37\lib\site-packages\mpf\devices\switch.py", line 149, in _initialize
    self.config['number'], config, self.config['platform_settings'])
  File "c:\users\tanner\appdata\local\programs\python\python37\lib\site-packages\mpf\platforms\fast\fast.py", line 665, in configure_switch
    number = self._parse_switch_number(number)
  File "c:\users\tanner\appdata\local\programs\python\python37\lib\site-packages\mpf\platforms\fast\fast.py", line 597, in _parse_switch_number
    raise AssertionError("Board {} does not exist for switch {}".format(board, number))
AssertionError: Board 2 does not exist for switch 2-1

The above exception was the direct cause of the following exception:

Traceback (most recent call last):
  File "c:\users\tanner\appdata\local\programs\python\python37\lib\site-packages\mpf\core\system_wide_device.py", line 17, in device_added_system_wide
    await self._initialize()
  File "c:\users\tanner\appdata\local\programs\python\python37\lib\site-packages\mpf\devices\switch.py", line 152, in _initialize
    self.class_label) from e
mpf.exceptions.config_file_error.ConfigFileError: Config File Error in switch: Failed to configure switch s_pop_left in platform. See error above Error Code: CFE-switch-2 (https://docs.missionpinball.org/en/0.55/logs/CFE-switch-2.html)
2022-10-11 22:45:24,661 : ERROR : asyncio : Task exception was never retrieved
future: <Task finished coro=<SystemWideDevice.device_added_system_wide() done, defined at c:\users\tanner\appdata\local\programs\python\python37\lib\site-packages\mpf\core\system_wide_device.py:15> exception=AssertionError('Failed to configure driver c_autolauncher in platform. See error above')>
Traceback (most recent call last):
  File "c:\users\tanner\appdata\local\programs\python\python37\lib\site-packages\mpf\devices\driver.py", line 107, in _initialize
    self.hw_driver = self.platform.configure_driver(config, self.config['number'], platform_settings)
  File "c:\users\tanner\appdata\local\programs\python\python37\lib\site-packages\mpf\platforms\fast\fast.py", line 533, in configure_driver
    number = self._parse_driver_number(number)
  File "c:\users\tanner\appdata\local\programs\python\python37\lib\site-packages\mpf\platforms\fast\fast.py", line 481, in _parse_driver_number
    raise AssertionError("Board {} does not exist for driver {}".format(board, number))
AssertionError: Board 3 does not exist for driver 3-0

The above exception was the direct cause of the following exception:

Traceback (most recent call last):
  File "c:\users\tanner\appdata\local\programs\python\python37\lib\site-packages\mpf\core\system_wide_device.py", line 17, in device_added_system_wide
    await self._initialize()
  File "c:\users\tanner\appdata\local\programs\python\python37\lib\site-packages\mpf\devices\driver.py", line 109, in _initialize
    raise AssertionError("Failed to configure driver {} in platform. See error above".format(self.name)) from e
AssertionError: Failed to configure driver c_autolauncher in platform. See error above
2022-10-11 22:45:24,661 : ERROR : asyncio : Task exception was never retrieved
future: <Task finished coro=<SystemWideDevice.device_added_system_wide() done, defined at c:\users\tanner\appdata\local\programs\python\python37\lib\site-packages\mpf\core\system_wide_device.py:15> exception=ConfigFileError('Failed to configure switch s_upper_rollover in platform. See error above')>
Traceback (most recent call last):
  File "c:\users\tanner\appdata\local\programs\python\python37\lib\site-packages\mpf\devices\switch.py", line 149, in _initialize
    self.config['number'], config, self.config['platform_settings'])
  File "c:\users\tanner\appdata\local\programs\python\python37\lib\site-packages\mpf\platforms\fast\fast.py", line 665, in configure_switch
    number = self._parse_switch_number(number)
  File "c:\users\tanner\appdata\local\programs\python\python37\lib\site-packages\mpf\platforms\fast\fast.py", line 597, in _parse_switch_number
    raise AssertionError("Board {} does not exist for switch {}".format(board, number))
AssertionError: Board 1 does not exist for switch 1-0

The above exception was the direct cause of the following exception:

Traceback (most recent call last):
  File "c:\users\tanner\appdata\local\programs\python\python37\lib\site-packages\mpf\core\system_wide_device.py", line 17, in device_added_system_wide
    await self._initialize()
  File "c:\users\tanner\appdata\local\programs\python\python37\lib\site-packages\mpf\devices\switch.py", line 152, in _initialize
    self.class_label) from e
mpf.exceptions.config_file_error.ConfigFileError: Config File Error in switch: Failed to configure switch s_upper_rollover in platform. See error above Error Code: CFE-switch-2 (https://docs.missionpinball.org/en/0.55/logs/CFE-switch-2.html)
2022-10-11 22:45:24,662 : ERROR : asyncio : Task exception was never retrieved
future: <Task finished coro=<SystemWideDevice.device_added_system_wide() done, defined at c:\users\tanner\appdata\local\programs\python\python37\lib\site-packages\mpf\core\system_wide_device.py:15> exception=ConfigFileError('Failed to configure switch s_bot_right in platform. See error above')>
Traceback (most recent call last):
  File "c:\users\tanner\appdata\local\programs\python\python37\lib\site-packages\mpf\devices\switch.py", line 149, in _initialize
    self.config['number'], config, self.config['platform_settings'])
  File "c:\users\tanner\appdata\local\programs\python\python37\lib\site-packages\mpf\platforms\fast\fast.py", line 665, in configure_switch
    number = self._parse_switch_number(number)
  File "c:\users\tanner\appdata\local\programs\python\python37\lib\site-packages\mpf\platforms\fast\fast.py", line 597, in _parse_switch_number
    raise AssertionError("Board {} does not exist for switch {}".format(board, number))
AssertionError: Board 4 does not exist for switch 4-2

The above exception was the direct cause of the following exception:

Traceback (most recent call last):
  File "c:\users\tanner\appdata\local\programs\python\python37\lib\site-packages\mpf\core\system_wide_device.py", line 17, in device_added_system_wide
    await self._initialize()
  File "c:\users\tanner\appdata\local\programs\python\python37\lib\site-packages\mpf\devices\switch.py", line 152, in _initialize
    self.class_label) from e
mpf.exceptions.config_file_error.ConfigFileError: Config File Error in switch: Failed to configure switch s_bot_right in platform. See error above Error Code: CFE-switch-2 (https://docs.missionpinball.org/en/0.55/logs/CFE-switch-2.html)
2022-10-11 22:45:24,662 : ERROR : asyncio : Task exception was never retrieved
future: <Task finished coro=<SystemWideDevice.device_added_system_wide() done, defined at c:\users\tanner\appdata\local\programs\python\python37\lib\site-packages\mpf\core\system_wide_device.py:15> exception=AssertionError('Failed to configure driver c_post_outlane in platform. See error above')>
Traceback (most recent call last):
  File "c:\users\tanner\appdata\local\programs\python\python37\lib\site-packages\mpf\devices\driver.py", line 107, in _initialize
    self.hw_driver = self.platform.configure_driver(config, self.config['number'], platform_settings)
  File "c:\users\tanner\appdata\local\programs\python\python37\lib\site-packages\mpf\platforms\fast\fast.py", line 533, in configure_driver
    number = self._parse_driver_number(number)
  File "c:\users\tanner\appdata\local\programs\python\python37\lib\site-packages\mpf\platforms\fast\fast.py", line 481, in _parse_driver_number
    raise AssertionError("Board {} does not exist for driver {}".format(board, number))
AssertionError: Board 2 does not exist for driver 2-2

The above exception was the direct cause of the following exception:

Traceback (most recent call last):
  File "c:\users\tanner\appdata\local\programs\python\python37\lib\site-packages\mpf\core\system_wide_device.py", line 17, in device_added_system_wide
    await self._initialize()
  File "c:\users\tanner\appdata\local\programs\python\python37\lib\site-packages\mpf\devices\driver.py", line 109, in _initialize
    raise AssertionError("Failed to configure driver {} in platform. See error above".format(self.name)) from e
AssertionError: Failed to configure driver c_post_outlane in platform. See error above
2022-10-11 22:45:24,662 : ERROR : asyncio : Task exception was never retrieved
future: <Task finished coro=<SystemWideDevice.device_added_system_wide() done, defined at c:\users\tanner\appdata\local\programs\python\python37\lib\site-packages\mpf\core\system_wide_device.py:15> exception=ConfigFileError('Failed to configure switch s_eos_left in platform. See error above')>
Traceback (most recent call last):
  File "c:\users\tanner\appdata\local\programs\python\python37\lib\site-packages\mpf\devices\switch.py", line 149, in _initialize
    self.config['number'], config, self.config['platform_settings'])
  File "c:\users\tanner\appdata\local\programs\python\python37\lib\site-packages\mpf\platforms\fast\fast.py", line 665, in configure_switch
    number = self._parse_switch_number(number)
  File "c:\users\tanner\appdata\local\programs\python\python37\lib\site-packages\mpf\platforms\fast\fast.py", line 597, in _parse_switch_number
    raise AssertionError("Board {} does not exist for switch {}".format(board, number))
AssertionError: Board 3 does not exist for switch 3-3

The above exception was the direct cause of the following exception:

Traceback (most recent call last):
  File "c:\users\tanner\appdata\local\programs\python\python37\lib\site-packages\mpf\core\system_wide_device.py", line 17, in device_added_system_wide
    await self._initialize()
  File "c:\users\tanner\appdata\local\programs\python\python37\lib\site-packages\mpf\devices\switch.py", line 152, in _initialize
    self.class_label) from e
mpf.exceptions.config_file_error.ConfigFileError: Config File Error in switch: Failed to configure switch s_eos_left in platform. See error above Error Code: CFE-switch-2 (https://docs.missionpinball.org/en/0.55/logs/CFE-switch-2.html)
2022-10-11 22:45:24,663 : ERROR : asyncio : Task exception was never retrieved
future: <Task finished coro=<SystemWideDevice.device_added_system_wide() done, defined at c:\users\tanner\appdata\local\programs\python\python37\lib\site-packages\mpf\core\system_wide_device.py:15> exception=ConfigFileError('Failed to configure switch s_sling_left in platform. See error above')>
Traceback (most recent call last):
  File "c:\users\tanner\appdata\local\programs\python\python37\lib\site-packages\mpf\devices\switch.py", line 149, in _initialize
    self.config['number'], config, self.config['platform_settings'])
  File "c:\users\tanner\appdata\local\programs\python\python37\lib\site-packages\mpf\platforms\fast\fast.py", line 665, in configure_switch
    number = self._parse_switch_number(number)
  File "c:\users\tanner\appdata\local\programs\python\python37\lib\site-packages\mpf\platforms\fast\fast.py", line 597, in _parse_switch_number
    raise AssertionError("Board {} does not exist for switch {}".format(board, number))
AssertionError: Board 2 does not exist for switch 2-2

The above exception was the direct cause of the following exception:

Traceback (most recent call last):
  File "c:\users\tanner\appdata\local\programs\python\python37\lib\site-packages\mpf\core\system_wide_device.py", line 17, in device_added_system_wide
    await self._initialize()
  File "c:\users\tanner\appdata\local\programs\python\python37\lib\site-packages\mpf\devices\switch.py", line 152, in _initialize
    self.class_label) from e
mpf.exceptions.config_file_error.ConfigFileError: Config File Error in switch: Failed to configure switch s_sling_left in platform. See error above Error Code: CFE-switch-2 (https://docs.missionpinball.org/en/0.55/logs/CFE-switch-2.html)
2022-10-11 22:45:24,663 : ERROR : asyncio : Task exception was never retrieved
future: <Task finished coro=<SystemWideDevice.device_added_system_wide() done, defined at c:\users\tanner\appdata\local\programs\python\python37\lib\site-packages\mpf\core\system_wide_device.py:15> exception=AssertionError('Failed to configure driver c_drop_right in platform. See error above')>
Traceback (most recent call last):
  File "c:\users\tanner\appdata\local\programs\python\python37\lib\site-packages\mpf\devices\driver.py", line 107, in _initialize
    self.hw_driver = self.platform.configure_driver(config, self.config['number'], platform_settings)
  File "c:\users\tanner\appdata\local\programs\python\python37\lib\site-packages\mpf\platforms\fast\fast.py", line 533, in configure_driver
    number = self._parse_driver_number(number)
  File "c:\users\tanner\appdata\local\programs\python\python37\lib\site-packages\mpf\platforms\fast\fast.py", line 481, in _parse_driver_number
    raise AssertionError("Board {} does not exist for driver {}".format(board, number))
AssertionError: Board 2 does not exist for driver 2-14

The above exception was the direct cause of the following exception:

Traceback (most recent call last):
  File "c:\users\tanner\appdata\local\programs\python\python37\lib\site-packages\mpf\core\system_wide_device.py", line 17, in device_added_system_wide
    await self._initialize()
  File "c:\users\tanner\appdata\local\programs\python\python37\lib\site-packages\mpf\devices\driver.py", line 109, in _initialize
    raise AssertionError("Failed to configure driver {} in platform. See error above".format(self.name)) from e
AssertionError: Failed to configure driver c_drop_right in platform. See error above
2022-10-11 22:45:24,663 : ERROR : asyncio : Task exception was never retrieved
future: <Task finished coro=<SystemWideDevice.device_added_system_wide() done, defined at c:\users\tanner\appdata\local\programs\python\python37\lib\site-packages\mpf\core\system_wide_device.py:15> exception=ConfigFileError('Failed to configure switch s_pop_right in platform. See error above')>
Traceback (most recent call last):
  File "c:\users\tanner\appdata\local\programs\python\python37\lib\site-packages\mpf\devices\switch.py", line 149, in _initialize
    self.config['number'], config, self.config['platform_settings'])
  File "c:\users\tanner\appdata\local\programs\python\python37\lib\site-packages\mpf\platforms\fast\fast.py", line 665, in configure_switch
    number = self._parse_switch_number(number)
  File "c:\users\tanner\appdata\local\programs\python\python37\lib\site-packages\mpf\platforms\fast\fast.py", line 597, in _parse_switch_number
    raise AssertionError("Board {} does not exist for switch {}".format(board, number))
AssertionError: Board 2 does not exist for switch 2-7

The above exception was the direct cause of the following exception:

Traceback (most recent call last):
  File "c:\users\tanner\appdata\local\programs\python\python37\lib\site-packages\mpf\core\system_wide_device.py", line 17, in device_added_system_wide
    await self._initialize()
  File "c:\users\tanner\appdata\local\programs\python\python37\lib\site-packages\mpf\devices\switch.py", line 152, in _initialize
    self.class_label) from e
mpf.exceptions.config_file_error.ConfigFileError: Config File Error in switch: Failed to configure switch s_pop_right in platform. See error above Error Code: CFE-switch-2 (https://docs.missionpinball.org/en/0.55/logs/CFE-switch-2.html)
2022-10-11 22:45:24,664 : ERROR : asyncio : Task exception was never retrieved
future: <Task finished coro=<SystemWideDevice.device_added_system_wide() done, defined at c:\users\tanner\appdata\local\programs\python\python37\lib\site-packages\mpf\core\system_wide_device.py:15> exception=AssertionError('Failed to configure driver c_trough in platform. See error above')>
Traceback (most recent call last):
  File "c:\users\tanner\appdata\local\programs\python\python37\lib\site-packages\mpf\devices\driver.py", line 107, in _initialize
    self.hw_driver = self.platform.configure_driver(config, self.config['number'], platform_settings)
  File "c:\users\tanner\appdata\local\programs\python\python37\lib\site-packages\mpf\platforms\fast\fast.py", line 533, in configure_driver
    number = self._parse_driver_number(number)
  File "c:\users\tanner\appdata\local\programs\python\python37\lib\site-packages\mpf\platforms\fast\fast.py", line 481, in _parse_driver_number
    raise AssertionError("Board {} does not exist for driver {}".format(board, number))
AssertionError: Board 3 does not exist for driver 3-1

The above exception was the direct cause of the following exception:

Traceback (most recent call last):
  File "c:\users\tanner\appdata\local\programs\python\python37\lib\site-packages\mpf\core\system_wide_device.py", line 17, in device_added_system_wide
    await self._initialize()
  File "c:\users\tanner\appdata\local\programs\python\python37\lib\site-packages\mpf\devices\driver.py", line 109, in _initialize
    raise AssertionError("Failed to configure driver {} in platform. See error above".format(self.name)) from e
AssertionError: Failed to configure driver c_trough in platform. See error above
2022-10-11 22:45:24,664 : ERROR : asyncio : Task exception was never retrieved
future: <Task finished coro=<SystemWideDevice.device_added_system_wide() done, defined at c:\users\tanner\appdata\local\programs\python\python37\lib\site-packages\mpf\core\system_wide_device.py:15> exception=ConfigFileError('Failed to configure switch s_upper_drop in platform. See error above')>
Traceback (most recent call last):
  File "c:\users\tanner\appdata\local\programs\python\python37\lib\site-packages\mpf\devices\switch.py", line 149, in _initialize
    self.config['number'], config, self.config['platform_settings'])
  File "c:\users\tanner\appdata\local\programs\python\python37\lib\site-packages\mpf\platforms\fast\fast.py", line 665, in configure_switch
    number = self._parse_switch_number(number)
  File "c:\users\tanner\appdata\local\programs\python\python37\lib\site-packages\mpf\platforms\fast\fast.py", line 597, in _parse_switch_number
    raise AssertionError("Board {} does not exist for switch {}".format(board, number))
AssertionError: Board 1 does not exist for switch 1-1

The above exception was the direct cause of the following exception:

Traceback (most recent call last):
  File "c:\users\tanner\appdata\local\programs\python\python37\lib\site-packages\mpf\core\system_wide_device.py", line 17, in device_added_system_wide
    await self._initialize()
  File "c:\users\tanner\appdata\local\programs\python\python37\lib\site-packages\mpf\devices\switch.py", line 152, in _initialize
    self.class_label) from e
mpf.exceptions.config_file_error.ConfigFileError: Config File Error in switch: Failed to configure switch s_upper_drop in platform. See error above Error Code: CFE-switch-2 (https://docs.missionpinball.org/en/0.55/logs/CFE-switch-2.html)
2022-10-11 22:45:24,664 : ERROR : asyncio : Task exception was never retrieved
future: <Task finished coro=<SystemWideDevice.device_added_system_wide() done, defined at c:\users\tanner\appdata\local\programs\python\python37\lib\site-packages\mpf\core\system_wide_device.py:15> exception=ConfigFileError('Failed to configure switch s_bot_back in platform. See error above')>
Traceback (most recent call last):
  File "c:\users\tanner\appdata\local\programs\python\python37\lib\site-packages\mpf\devices\switch.py", line 149, in _initialize
    self.config['number'], config, self.config['platform_settings'])
  File "c:\users\tanner\appdata\local\programs\python\python37\lib\site-packages\mpf\platforms\fast\fast.py", line 665, in configure_switch
    number = self._parse_switch_number(number)
  File "c:\users\tanner\appdata\local\programs\python\python37\lib\site-packages\mpf\platforms\fast\fast.py", line 597, in _parse_switch_number
    raise AssertionError("Board {} does not exist for switch {}".format(board, number))
AssertionError: Board 4 does not exist for switch 4-0

The above exception was the direct cause of the following exception:

Traceback (most recent call last):
  File "c:\users\tanner\appdata\local\programs\python\python37\lib\site-packages\mpf\core\system_wide_device.py", line 17, in device_added_system_wide
    await self._initialize()
  File "c:\users\tanner\appdata\local\programs\python\python37\lib\site-packages\mpf\devices\switch.py", line 152, in _initialize
    self.class_label) from e
mpf.exceptions.config_file_error.ConfigFileError: Config File Error in switch: Failed to configure switch s_bot_back in platform. See error above Error Code: CFE-switch-2 (https://docs.missionpinball.org/en/0.55/logs/CFE-switch-2.html)
2022-10-11 22:45:24,665 : ERROR : asyncio : Task exception was never retrieved
future: <Task finished coro=<SystemWideDevice.device_added_system_wide() done, defined at c:\users\tanner\appdata\local\programs\python\python37\lib\site-packages\mpf\core\system_wide_device.py:15> exception=AssertionError('Failed to configure driver c_left_sling in platform. See error above')>
Traceback (most recent call last):
  File "c:\users\tanner\appdata\local\programs\python\python37\lib\site-packages\mpf\devices\driver.py", line 107, in _initialize
    self.hw_driver = self.platform.configure_driver(config, self.config['number'], platform_settings)
  File "c:\users\tanner\appdata\local\programs\python\python37\lib\site-packages\mpf\platforms\fast\fast.py", line 533, in configure_driver
    number = self._parse_driver_number(number)
  File "c:\users\tanner\appdata\local\programs\python\python37\lib\site-packages\mpf\platforms\fast\fast.py", line 481, in _parse_driver_number
    raise AssertionError("Board {} does not exist for driver {}".format(board, number))
AssertionError: Board 2 does not exist for driver 2-3

The above exception was the direct cause of the following exception:

Traceback (most recent call last):
  File "c:\users\tanner\appdata\local\programs\python\python37\lib\site-packages\mpf\core\system_wide_device.py", line 17, in device_added_system_wide
    await self._initialize()
  File "c:\users\tanner\appdata\local\programs\python\python37\lib\site-packages\mpf\devices\driver.py", line 109, in _initialize
    raise AssertionError("Failed to configure driver {} in platform. See error above".format(self.name)) from e
AssertionError: Failed to configure driver c_left_sling in platform. See error above
2022-10-11 22:45:24,665 : ERROR : asyncio : Task exception was never retrieved
future: <Task finished coro=<SystemWideDevice.device_added_system_wide() done, defined at c:\users\tanner\appdata\local\programs\python\python37\lib\site-packages\mpf\core\system_wide_device.py:15> exception=ConfigFileError('Failed to configure switch s_sling_right in platform. See error above')>
Traceback (most recent call last):
  File "c:\users\tanner\appdata\local\programs\python\python37\lib\site-packages\mpf\devices\switch.py", line 149, in _initialize
    self.config['number'], config, self.config['platform_settings'])
  File "c:\users\tanner\appdata\local\programs\python\python37\lib\site-packages\mpf\platforms\fast\fast.py", line 665, in configure_switch
    number = self._parse_switch_number(number)
  File "c:\users\tanner\appdata\local\programs\python\python37\lib\site-packages\mpf\platforms\fast\fast.py", line 597, in _parse_switch_number
    raise AssertionError("Board {} does not exist for switch {}".format(board, number))
AssertionError: Board 2 does not exist for switch 2-15

The above exception was the direct cause of the following exception:

Traceback (most recent call last):
  File "c:\users\tanner\appdata\local\programs\python\python37\lib\site-packages\mpf\core\system_wide_device.py", line 17, in device_added_system_wide
    await self._initialize()
  File "c:\users\tanner\appdata\local\programs\python\python37\lib\site-packages\mpf\devices\switch.py", line 152, in _initialize
    self.class_label) from e
mpf.exceptions.config_file_error.ConfigFileError: Config File Error in switch: Failed to configure switch s_sling_right in platform. See error above Error Code: CFE-switch-2 (https://docs.missionpinball.org/en/0.55/logs/CFE-switch-2.html)
2022-10-11 22:45:24,665 : ERROR : asyncio : Task exception was never retrieved
future: <Task finished coro=<SystemWideDevice.device_added_system_wide() done, defined at c:\users\tanner\appdata\local\programs\python\python37\lib\site-packages\mpf\core\system_wide_device.py:15> exception=AssertionError('Failed to configure driver c_bot_top_flipper in platform. See error above')>
Traceback (most recent call last):
  File "c:\users\tanner\appdata\local\programs\python\python37\lib\site-packages\mpf\devices\driver.py", line 107, in _initialize
    self.hw_driver = self.platform.configure_driver(config, self.config['number'], platform_settings)
  File "c:\users\tanner\appdata\local\programs\python\python37\lib\site-packages\mpf\platforms\fast\fast.py", line 533, in configure_driver
    number = self._parse_driver_number(number)
  File "c:\users\tanner\appdata\local\programs\python\python37\lib\site-packages\mpf\platforms\fast\fast.py", line 481, in _parse_driver_number
    raise AssertionError("Board {} does not exist for driver {}".format(board, number))
AssertionError: Board 4 does not exist for driver 4-1

The above exception was the direct cause of the following exception:

Traceback (most recent call last):
  File "c:\users\tanner\appdata\local\programs\python\python37\lib\site-packages\mpf\core\system_wide_device.py", line 17, in device_added_system_wide
    await self._initialize()
  File "c:\users\tanner\appdata\local\programs\python\python37\lib\site-packages\mpf\devices\driver.py", line 109, in _initialize
    raise AssertionError("Failed to configure driver {} in platform. See error above".format(self.name)) from e
AssertionError: Failed to configure driver c_bot_top_flipper in platform. See error above
2022-10-11 22:45:24,666 : ERROR : asyncio : Task exception was never retrieved
future: <Task finished coro=<SystemWideDevice.device_added_system_wide() done, defined at c:\users\tanner\appdata\local\programs\python\python37\lib\site-packages\mpf\core\system_wide_device.py:15> exception=ConfigFileError('Failed to configure switch s_vuk_top in platform. See error above')>
Traceback (most recent call last):
  File "c:\users\tanner\appdata\local\programs\python\python37\lib\site-packages\mpf\devices\switch.py", line 149, in _initialize
    self.config['number'], config, self.config['platform_settings'])
  File "c:\users\tanner\appdata\local\programs\python\python37\lib\site-packages\mpf\platforms\fast\fast.py", line 665, in configure_switch
    number = self._parse_switch_number(number)
  File "c:\users\tanner\appdata\local\programs\python\python37\lib\site-packages\mpf\platforms\fast\fast.py", line 597, in _parse_switch_number
    raise AssertionError("Board {} does not exist for switch {}".format(board, number))
AssertionError: Board 2 does not exist for switch 2-12

The above exception was the direct cause of the following exception:

Traceback (most recent call last):
  File "c:\users\tanner\appdata\local\programs\python\python37\lib\site-packages\mpf\core\system_wide_device.py", line 17, in device_added_system_wide
    await self._initialize()
  File "c:\users\tanner\appdata\local\programs\python\python37\lib\site-packages\mpf\devices\switch.py", line 152, in _initialize
    self.class_label) from e
mpf.exceptions.config_file_error.ConfigFileError: Config File Error in switch: Failed to configure switch s_vuk_top in platform. See error above Error Code: CFE-switch-2 (https://docs.missionpinball.org/en/0.55/logs/CFE-switch-2.html)
2022-10-11 22:45:24,666 : ERROR : asyncio : Task exception was never retrieved
future: <Task finished coro=<SystemWideDevice.device_added_system_wide() done, defined at c:\users\tanner\appdata\local\programs\python\python37\lib\site-packages\mpf\core\system_wide_device.py:15> exception=AssertionError('Failed to configure driver c_bot_bot_flipper in platform. See error above')>
Traceback (most recent call last):
  File "c:\users\tanner\appdata\local\programs\python\python37\lib\site-packages\mpf\devices\driver.py", line 107, in _initialize
    self.hw_driver = self.platform.configure_driver(config, self.config['number'], platform_settings)
  File "c:\users\tanner\appdata\local\programs\python\python37\lib\site-packages\mpf\platforms\fast\fast.py", line 533, in configure_driver
    number = self._parse_driver_number(number)
  File "c:\users\tanner\appdata\local\programs\python\python37\lib\site-packages\mpf\platforms\fast\fast.py", line 481, in _parse_driver_number
    raise AssertionError("Board {} does not exist for driver {}".format(board, number))
AssertionError: Board 4 does not exist for driver 4-3

The above exception was the direct cause of the following exception:

Traceback (most recent call last):
  File "c:\users\tanner\appdata\local\programs\python\python37\lib\site-packages\mpf\core\system_wide_device.py", line 17, in device_added_system_wide
    await self._initialize()
  File "c:\users\tanner\appdata\local\programs\python\python37\lib\site-packages\mpf\devices\driver.py", line 109, in _initialize
    raise AssertionError("Failed to configure driver {} in platform. See error above".format(self.name)) from e
AssertionError: Failed to configure driver c_bot_bot_flipper in platform. See error above
2022-10-11 22:45:24,667 : ERROR : asyncio : Task exception was never retrieved
future: <Task finished coro=<SystemWideDevice.device_added_system_wide() done, defined at c:\users\tanner\appdata\local\programs\python\python37\lib\site-packages\mpf\core\system_wide_device.py:15> exception=ConfigFileError('Failed to configure switch s_vuk_right in platform. See error above')>
Traceback (most recent call last):
  File "c:\users\tanner\appdata\local\programs\python\python37\lib\site-packages\mpf\devices\switch.py", line 149, in _initialize
    self.config['number'], config, self.config['platform_settings'])
  File "c:\users\tanner\appdata\local\programs\python\python37\lib\site-packages\mpf\platforms\fast\fast.py", line 665, in configure_switch
    number = self._parse_switch_number(number)
  File "c:\users\tanner\appdata\local\programs\python\python37\lib\site-packages\mpf\platforms\fast\fast.py", line 597, in _parse_switch_number
    raise AssertionError("Board {} does not exist for switch {}".format(board, number))
AssertionError: Board 2 does not exist for switch 2-11

The above exception was the direct cause of the following exception:

Traceback (most recent call last):
  File "c:\users\tanner\appdata\local\programs\python\python37\lib\site-packages\mpf\core\system_wide_device.py", line 17, in device_added_system_wide
    await self._initialize()
  File "c:\users\tanner\appdata\local\programs\python\python37\lib\site-packages\mpf\devices\switch.py", line 152, in _initialize
    self.class_label) from e
mpf.exceptions.config_file_error.ConfigFileError: Config File Error in switch: Failed to configure switch s_vuk_right in platform. See error above Error Code: CFE-switch-2 (https://docs.missionpinball.org/en/0.55/logs/CFE-switch-2.html)
2022-10-11 22:45:24,667 : ERROR : asyncio : Task exception was never retrieved
future: <Task finished coro=<SystemWideDevice.device_added_system_wide() done, defined at c:\users\tanner\appdata\local\programs\python\python37\lib\site-packages\mpf\core\system_wide_device.py:15> exception=AssertionError('Failed to configure driver c_bot_bot_flipper_hold in platform. See error above')>
Traceback (most recent call last):
  File "c:\users\tanner\appdata\local\programs\python\python37\lib\site-packages\mpf\devices\driver.py", line 107, in _initialize
    self.hw_driver = self.platform.configure_driver(config, self.config['number'], platform_settings)
  File "c:\users\tanner\appdata\local\programs\python\python37\lib\site-packages\mpf\platforms\fast\fast.py", line 533, in configure_driver
    number = self._parse_driver_number(number)
  File "c:\users\tanner\appdata\local\programs\python\python37\lib\site-packages\mpf\platforms\fast\fast.py", line 481, in _parse_driver_number
    raise AssertionError("Board {} does not exist for driver {}".format(board, number))
AssertionError: Board 4 does not exist for driver 4-0

The above exception was the direct cause of the following exception:

Traceback (most recent call last):
  File "c:\users\tanner\appdata\local\programs\python\python37\lib\site-packages\mpf\core\system_wide_device.py", line 17, in device_added_system_wide
    await self._initialize()
  File "c:\users\tanner\appdata\local\programs\python\python37\lib\site-packages\mpf\devices\driver.py", line 109, in _initialize
    raise AssertionError("Failed to configure driver {} in platform. See error above".format(self.name)) from e
AssertionError: Failed to configure driver c_bot_bot_flipper_hold in platform. See error above
2022-10-11 22:45:24,667 : ERROR : asyncio : Task exception was never retrieved
future: <Task finished coro=<SystemWideDevice.device_added_system_wide() done, defined at c:\users\tanner\appdata\local\programs\python\python37\lib\site-packages\mpf\core\system_wide_device.py:15> exception=ConfigFileError('Failed to configure switch s_drop_single in platform. See error above')>
Traceback (most recent call last):
  File "c:\users\tanner\appdata\local\programs\python\python37\lib\site-packages\mpf\devices\switch.py", line 149, in _initialize
    self.config['number'], config, self.config['platform_settings'])
  File "c:\users\tanner\appdata\local\programs\python\python37\lib\site-packages\mpf\platforms\fast\fast.py", line 665, in configure_switch
    number = self._parse_switch_number(number)
  File "c:\users\tanner\appdata\local\programs\python\python37\lib\site-packages\mpf\platforms\fast\fast.py", line 597, in _parse_switch_number
    raise AssertionError("Board {} does not exist for switch {}".format(board, number))
AssertionError: Board 2 does not exist for switch 2-10

The above exception was the direct cause of the following exception:

Traceback (most recent call last):
  File "c:\users\tanner\appdata\local\programs\python\python37\lib\site-packages\mpf\core\system_wide_device.py", line 17, in device_added_system_wide
    await self._initialize()
  File "c:\users\tanner\appdata\local\programs\python\python37\lib\site-packages\mpf\devices\switch.py", line 152, in _initialize
    self.class_label) from e
mpf.exceptions.config_file_error.ConfigFileError: Config File Error in switch: Failed to configure switch s_drop_single in platform. See error above Error Code: CFE-switch-2 (https://docs.missionpinball.org/en/0.55/logs/CFE-switch-2.html)
2022-10-11 22:45:24,668 : ERROR : asyncio : Task exception was never retrieved
future: <Task finished coro=<SystemWideDevice.device_added_system_wide() done, defined at c:\users\tanner\appdata\local\programs\python\python37\lib\site-packages\mpf\core\system_wide_device.py:15> exception=ConfigFileError('Failed to configure switch s_trough_6 in platform. See error above')>
Traceback (most recent call last):
  File "c:\users\tanner\appdata\local\programs\python\python37\lib\site-packages\mpf\devices\switch.py", line 149, in _initialize
    self.config['number'], config, self.config['platform_settings'])
  File "c:\users\tanner\appdata\local\programs\python\python37\lib\site-packages\mpf\platforms\fast\fast.py", line 665, in configure_switch
    number = self._parse_switch_number(number)
  File "c:\users\tanner\appdata\local\programs\python\python37\lib\site-packages\mpf\platforms\fast\fast.py", line 597, in _parse_switch_number
    raise AssertionError("Board {} does not exist for switch {}".format(board, number))
AssertionError: Board 3 does not exist for switch 3-8

The above exception was the direct cause of the following exception:

Traceback (most recent call last):
  File "c:\users\tanner\appdata\local\programs\python\python37\lib\site-packages\mpf\core\system_wide_device.py", line 17, in device_added_system_wide
    await self._initialize()
  File "c:\users\tanner\appdata\local\programs\python\python37\lib\site-packages\mpf\devices\switch.py", line 152, in _initialize
    self.class_label) from e
mpf.exceptions.config_file_error.ConfigFileError: Config File Error in switch: Failed to configure switch s_trough_6 in platform. See error above Error Code: CFE-switch-2 (https://docs.missionpinball.org/en/0.55/logs/CFE-switch-2.html)
2022-10-11 22:45:24,668 : ERROR : asyncio : Task exception was never retrieved
future: <Task finished coro=<SystemWideDevice.device_added_system_wide() done, defined at c:\users\tanner\appdata\local\programs\python\python37\lib\site-packages\mpf\core\system_wide_device.py:15> exception=ConfigFileError('Failed to configure switch s_trough_5 in platform. See error above')>
Traceback (most recent call last):
  File "c:\users\tanner\appdata\local\programs\python\python37\lib\site-packages\mpf\devices\switch.py", line 149, in _initialize
    self.config['number'], config, self.config['platform_settings'])
  File "c:\users\tanner\appdata\local\programs\python\python37\lib\site-packages\mpf\platforms\fast\fast.py", line 665, in configure_switch
    number = self._parse_switch_number(number)
  File "c:\users\tanner\appdata\local\programs\python\python37\lib\site-packages\mpf\platforms\fast\fast.py", line 597, in _parse_switch_number
    raise AssertionError("Board {} does not exist for switch {}".format(board, number))
AssertionError: Board 3 does not exist for switch 3-9

The above exception was the direct cause of the following exception:

Traceback (most recent call last):
  File "c:\users\tanner\appdata\local\programs\python\python37\lib\site-packages\mpf\core\system_wide_device.py", line 17, in device_added_system_wide
    await self._initialize()
  File "c:\users\tanner\appdata\local\programs\python\python37\lib\site-packages\mpf\devices\switch.py", line 152, in _initialize
    self.class_label) from e
mpf.exceptions.config_file_error.ConfigFileError: Config File Error in switch: Failed to configure switch s_trough_5 in platform. See error above Error Code: CFE-switch-2 (https://docs.missionpinball.org/en/0.55/logs/CFE-switch-2.html)
2022-10-11 22:45:24,668 : ERROR : asyncio : Task exception was never retrieved
future: <Task finished coro=<SystemWideDevice.device_added_system_wide() done, defined at c:\users\tanner\appdata\local\programs\python\python37\lib\site-packages\mpf\core\system_wide_device.py:15> exception=ConfigFileError('Failed to configure switch s_trough_4 in platform. See error above')>
Traceback (most recent call last):
  File "c:\users\tanner\appdata\local\programs\python\python37\lib\site-packages\mpf\devices\switch.py", line 149, in _initialize
    self.config['number'], config, self.config['platform_settings'])
  File "c:\users\tanner\appdata\local\programs\python\python37\lib\site-packages\mpf\platforms\fast\fast.py", line 665, in configure_switch
    number = self._parse_switch_number(number)
  File "c:\users\tanner\appdata\local\programs\python\python37\lib\site-packages\mpf\platforms\fast\fast.py", line 597, in _parse_switch_number
    raise AssertionError("Board {} does not exist for switch {}".format(board, number))
AssertionError: Board 3 does not exist for switch 3-10

The above exception was the direct cause of the following exception:

Traceback (most recent call last):
  File "c:\users\tanner\appdata\local\programs\python\python37\lib\site-packages\mpf\core\system_wide_device.py", line 17, in device_added_system_wide
    await self._initialize()
  File "c:\users\tanner\appdata\local\programs\python\python37\lib\site-packages\mpf\devices\switch.py", line 152, in _initialize
    self.class_label) from e
mpf.exceptions.config_file_error.ConfigFileError: Config File Error in switch: Failed to configure switch s_trough_4 in platform. See error above Error Code: CFE-switch-2 (https://docs.missionpinball.org/en/0.55/logs/CFE-switch-2.html)
2022-10-11 22:45:24,669 : ERROR : asyncio : Task exception was never retrieved
future: <Task finished coro=<SystemWideDevice.device_added_system_wide() done, defined at c:\users\tanner\appdata\local\programs\python\python37\lib\site-packages\mpf\core\system_wide_device.py:15> exception=AssertionError('Failed to configure driver c_bot_vuk in platform. See error above')>
Traceback (most recent call last):
  File "c:\users\tanner\appdata\local\programs\python\python37\lib\site-packages\mpf\devices\driver.py", line 107, in _initialize
    self.hw_driver = self.platform.configure_driver(config, self.config['number'], platform_settings)
  File "c:\users\tanner\appdata\local\programs\python\python37\lib\site-packages\mpf\platforms\fast\fast.py", line 533, in configure_driver
    number = self._parse_driver_number(number)
  File "c:\users\tanner\appdata\local\programs\python\python37\lib\site-packages\mpf\platforms\fast\fast.py", line 481, in _parse_driver_number
    raise AssertionError("Board {} does not exist for driver {}".format(board, number))
AssertionError: Board 4 does not exist for driver 4-2

The above exception was the direct cause of the following exception:

Traceback (most recent call last):
  File "c:\users\tanner\appdata\local\programs\python\python37\lib\site-packages\mpf\core\system_wide_device.py", line 17, in device_added_system_wide
    await self._initialize()
  File "c:\users\tanner\appdata\local\programs\python\python37\lib\site-packages\mpf\devices\driver.py", line 109, in _initialize
    raise AssertionError("Failed to configure driver {} in platform. See error above".format(self.name)) from e
AssertionError: Failed to configure driver c_bot_vuk in platform. See error above
2022-10-11 22:45:24,670 : INFO : EventManager : Event: ======'init_phase_2'====== Args={}
2022-10-11 22:45:24,670 : INFO : Machine : Starting the main run loop.
2022-10-11 22:45:24,672 : INFO : Machine : Shutting down...
2022-10-11 22:45:24,673 : INFO : EventManager : Event: ======'shutdown'====== Args={}
2022-10-11 22:45:24,673 : ERROR : asyncio : Exception in callback EventManager._async_handler_done(<QueuedEvent>)(<Task finishe...te 'number'")>) at c:\users\tanner\appdata\local\programs\python\python37\lib\site-packages\mpf\core\events.py:112
handle: <Handle EventManager._async_handler_done(<QueuedEvent>)(<Task finishe...te 'number'")>) at c:\users\tanner\appdata\local\programs\python\python37\lib\site-packages\mpf\core\events.py:112>
Traceback (most recent call last):
  File "c:\users\tanner\appdata\local\programs\python\python37\lib\asyncio\events.py", line 88, in _run
    self._context.run(self._callback, *self._args)
  File "c:\users\tanner\appdata\local\programs\python\python37\lib\site-packages\mpf\core\events.py", line 115, in _async_handler_done
    future.result()
  File "c:\users\tanner\appdata\local\programs\python\python37\lib\site-packages\mpf\core\switch_controller.py", line 82, in _initialize_switches
    await self.update_switches_from_hw()
  File "c:\users\tanner\appdata\local\programs\python\python37\lib\site-packages\mpf\core\switch_controller.py", line 104, in update_switches_from_hw
    switches.add((switch, switch.hw_switch.number))
AttributeError: 'NoneType' object has no attribute 'number'
2022-10-11 22:45:24,774 : ERROR : FAST : Stop called on serial connection com9
2022-10-11 22:45:24,774 : ERROR : FAST : Stop called on serial connection com10
2022-10-11 22:45:24,995 : ERROR : asyncio : Task was destroyed but it is pending!
task: <Task pending coro=<Event.wait() running at c:\users\tanner\appdata\local\programs\python\python37\lib\asyncio\locks.py:293> wait_for=<Future cancelled>>
2022-10-11 22:45:24,996 : ERROR : Machine : Runtime Exception
Traceback (most recent call last):
  File "c:\users\tanner\appdata\local\programs\python\python37\lib\site-packages\mpf\devices\switch.py", line 149, in _initialize
    self.config['number'], config, self.config['platform_settings'])
  File "c:\users\tanner\appdata\local\programs\python\python37\lib\site-packages\mpf\platforms\fast\fast.py", line 665, in configure_switch
    number = self._parse_switch_number(number)
  File "c:\users\tanner\appdata\local\programs\python\python37\lib\site-packages\mpf\platforms\fast\fast.py", line 597, in _parse_switch_number
    raise AssertionError("Board {} does not exist for switch {}".format(board, number))
AssertionError: Board 3 does not exist for switch 3-11

The above exception was the direct cause of the following exception:

Traceback (most recent call last):
  File "c:\users\tanner\appdata\local\programs\python\python37\lib\site-packages\mpf\core\machine.py", line 769, in _run_loop
    raise self._exception['exception']
  File "c:\users\tanner\appdata\local\programs\python\python37\lib\site-packages\mpf\core\system_wide_device.py", line 17, in device_added_system_wide
    await self._initialize()
  File "c:\users\tanner\appdata\local\programs\python\python37\lib\site-packages\mpf\devices\switch.py", line 152, in _initialize
    self.class_label) from e
mpf.exceptions.config_file_error.ConfigFileError: Config File Error in switch: Failed to configure switch s_trough_3 in platform. See error above Error Code: CFE-switch-2 (https://docs.missionpinball.org/en/0.55/logs/CFE-switch-2.html)
2022-10-11 22:45:32,437 : INFO : root : MPF run loop ended.
