2022-10-12 07:32:46,260 : INFO : root : Loading config.
2022-10-12 07:32:46,263 : INFO : YamlMultifileConfigLoader : Machine config file #1: config.yaml
2022-10-12 07:32:46,264 : WARNING : ConfigProcessor : Config file in cache changed: c:\trashland_2\config\config.yaml
2022-10-12 07:32:46,264 : INFO : ConfigProcessor : Loading config from file c:\users\tanner\appdata\local\programs\python\python37\lib\site-packages\mpf\mpfconfig.yaml.
2022-10-12 07:32:46,339 : INFO : ConfigProcessor : Loading config: c:\users\tanner\appdata\local\programs\python\python37\lib\site-packages\mpf\mpfconfig.yaml
2022-10-12 07:32:46,339 : INFO : ConfigProcessor : Loading config from file c:\trashland_2\config\config.yaml.
2022-10-12 07:32:46,442 : INFO : ConfigProcessor : Loading config: c:\trashland_2\config\config.yaml
2022-10-12 07:32:46,445 : INFO : ConfigProcessor : Config file cache created: C:\Users\Tanner\AppData\Local\Temp\a6762098cb994b55cb03a478b26022ee.mpf_cache
2022-10-12 07:32:46,512 : INFO : ConfigProcessor : Loading config from cache: C:\Users\Tanner\AppData\Local\Temp\9cf7ccc27b21f4d6162237fadfc53e5a.mpf_cache
2022-10-12 07:32:46,513 : INFO : ConfigProcessor : Loading config from cache: C:\Users\Tanner\AppData\Local\Temp\c215df352878fee5d54f1a5ec5b16e7c.mpf_cache
2022-10-12 07:32:46,514 : INFO : ConfigProcessor : Loading config from cache: C:\Users\Tanner\AppData\Local\Temp\708062243e0edcfa77dd6b1521bd0d4e.mpf_cache
2022-10-12 07:32:46,514 : INFO : ConfigProcessor : Loading config from cache: C:\Users\Tanner\AppData\Local\Temp\c4174472f67f7b070dd6fb437c6feb0c.mpf_cache
2022-10-12 07:32:46,515 : INFO : ConfigProcessor : Loading config from cache: C:\Users\Tanner\AppData\Local\Temp\abaa92c43d134e3392cbb2346e6a16be.mpf_cache
2022-10-12 07:32:46,516 : INFO : ConfigProcessor : Loading config from cache: C:\Users\Tanner\AppData\Local\Temp\fc46d53fcb9fe6b8abf783d9c813390a.mpf_cache
2022-10-12 07:32:46,518 : INFO : Machine : Mission Pinball Framework Core Engine v0.55.0
2022-10-12 07:32:46,518 : INFO : Machine : Command line arguments: {'no_load_cache': False, 'create_config_cache': True, 'bcp': False, 'configfile': ['config.yaml'], 'force_assets_load': False, 'jsonlogging': False, 'logfile': 'logs\\2022-10-12-07-32-46-mpf-DESKTOP-7HNFDQ5.log', 'pause': False, 'production': False, 'text_ui': True, 'loglevel': 15, 'consoleloglevel': 20, 'force_platform': None, 'syslog_address': None, 'mc_file_name': None, 'no_sound': False}
2022-10-12 07:32:46,518 : INFO : Machine : MPF path: c:\users\tanner\appdata\local\programs\python\python37\lib\site-packages\mpf
2022-10-12 07:32:46,518 : INFO : Machine : Machine path: c:\trashland_2
2022-10-12 07:32:46,518 : INFO : Machine : Platform: win32
2022-10-12 07:32:46,518 : INFO : Machine : Python executable location: c:\users\tanner\appdata\local\programs\python\python37\python.exe
2022-10-12 07:32:46,518 : INFO : Machine : Python version: 3.7.8 (64-bit)
2022-10-12 07:32:46,520 : INFO : Machine : Initialise MPF.
2022-10-12 07:32:46,792 : INFO : FAST : Connecting to com9 at 921600bps
2022-10-12 07:32:46,829 : INFO : FAST : Connected! Processor: NET, Board Type: FP-CPU-002-2, Firmware: 01.05
2022-10-12 07:32:46,829 : INFO : EventManager : Event: ======'machine_var_fast_net_firmware'====== Args={'value': '01.05', 'prev_value': None, 'change': True}
2022-10-12 07:32:46,829 : INFO : EventManager : Event: ======'machine_var_fast_net_model'====== Args={'value': 'FP-CPU-002-2', 'prev_value': None, 'change': True}
2022-10-12 07:32:49,203 : WARNING : FAST : Got unexpected message from FAST: -N:11
2022-10-12 07:32:49,203 : WARNING : FAST : Got unexpected message from FAST: -N:38
2022-10-12 07:32:49,203 : WARNING : FAST : Got unexpected message from FAST: -N:40
2022-10-12 07:32:49,203 : WARNING : FAST : Got unexpected message from FAST: -N:41
2022-10-12 07:32:49,203 : WARNING : FAST : Got unexpected message from FAST: -N:43
2022-10-12 07:32:49,203 : WARNING : FAST : Got unexpected message from FAST: -N:44
2022-10-12 07:32:49,203 : WARNING : FAST : Got unexpected message from FAST: -N:5D
2022-10-12 07:32:49,313 : INFO : FAST : Connecting to com10 at 921600bps
2022-10-12 07:32:49,317 : INFO : Machine : Shutting down...
2022-10-12 07:32:49,317 : INFO : EventManager : Event: ======'shutdown'====== Args={}
2022-10-12 07:32:49,408 : ERROR : FAST : Stop called on serial connection com9
2022-10-12 07:32:49,518 : ERROR : Machine : Failed to initialise MPF
Traceback (most recent call last):
  File "c:\users\tanner\appdata\local\programs\python\python37\lib\site-packages\mpf\platforms\fast\fast.py", line 311, in _connect_to_hardware
    await comm.connect()
  File "c:\users\tanner\appdata\local\programs\python\python37\lib\site-packages\mpf\platforms\base_serial_communicator.py", line 45, in connect
    await self._connect_to_hardware(self.port, self.baud, self.xonxoff)
  File "c:\users\tanner\appdata\local\programs\python\python37\lib\site-packages\mpf\platforms\base_serial_communicator.py", line 54, in _connect_to_hardware
    self.reader, self.writer = await connector
  File "c:\users\tanner\appdata\local\programs\python\python37\lib\site-packages\mpf\core\clock.py", line 155, in open_serial_connection
    **kwargs)
  File "c:\users\tanner\appdata\local\programs\python\python37\lib\asyncio\coroutines.py", line 120, in coro
    res = func(*args, **kw)
  File "c:\users\tanner\appdata\local\programs\python\python37\lib\site-packages\serial_asyncio\__init__.py", line 410, in create_serial_connection
    ser = serial.serial_for_url(*args, **kwargs)
  File "c:\users\tanner\appdata\local\programs\python\python37\lib\site-packages\serial\__init__.py", line 90, in serial_for_url
    instance.open()
  File "c:\users\tanner\appdata\local\programs\python\python37\lib\site-packages\serial\serialwin32.py", line 64, in open
    raise SerialException("could not open port {!r}: {!r}".format(self.portstr, ctypes.WinError()))
serial.serialutil.SerialException: could not open port 'com10': PermissionError(13, 'Access is denied.', None, 5)

The above exception was the direct cause of the following exception:

Traceback (most recent call last):
  File "c:\users\tanner\appdata\local\programs\python\python37\lib\site-packages\mpf\core\machine.py", line 673, in initialise_mpf
    raise init.exception()
  File "c:\users\tanner\appdata\local\programs\python\python37\lib\site-packages\mpf\core\machine.py", line 244, in initialise
    await self.initialise_core_and_hardware()
  File "c:\users\tanner\appdata\local\programs\python\python37\lib\site-packages\mpf\core\machine.py", line 240, in initialise_core_and_hardware
    await self._initialize_platforms()
  File "c:\users\tanner\appdata\local\programs\python\python37\lib\site-packages\mpf\core\machine.py", line 331, in _initialize_platforms
    result.result()
  File "c:\users\tanner\appdata\local\programs\python\python37\lib\site-packages\mpf\platforms\fast\fast.py", line 178, in initialize
    await self._connect_to_hardware()
  File "c:\users\tanner\appdata\local\programs\python\python37\lib\site-packages\mpf\platforms\fast\fast.py", line 315, in _connect_to_hardware
    "port".format(port), 1, self.log.name) from e
mpf.exceptions.runtime_error.MpfRuntimeError: Runtime Error in FAST: Could not open serial port com10. Check if you configured the correct port in the fast config section and if you got sufficient permissions to that port Error Code: RE-FAST-1 (https://docs.missionpinball.org/en/0.55/logs/RE-FAST-1.html)
2022-10-12 07:32:59,623 : INFO : root : MPF run loop ended.
