2022-10-06 14:06:04,373 : INFO : root : Loading config.
2022-10-06 14:06:04,376 : INFO : YamlMultifileConfigLoader : Machine config file #1: config.yaml
2022-10-06 14:06:04,376 : WARNING : ConfigProcessor : Config file in cache changed: c:\trashland_2\config\config.yaml
2022-10-06 14:06:04,376 : INFO : ConfigProcessor : Loading config from file c:\users\tanner\appdata\local\programs\python\python37\lib\site-packages\mpf\mpfconfig.yaml.
2022-10-06 14:06:04,448 : INFO : ConfigProcessor : Loading config: c:\users\tanner\appdata\local\programs\python\python37\lib\site-packages\mpf\mpfconfig.yaml
2022-10-06 14:06:04,449 : INFO : ConfigProcessor : Loading config from file c:\trashland_2\config\config.yaml.
2022-10-06 14:06:04,548 : INFO : ConfigProcessor : Loading config: c:\trashland_2\config\config.yaml
2022-10-06 14:06:04,550 : INFO : ConfigProcessor : Config file cache created: C:\Users\Tanner\AppData\Local\Temp\a6762098cb994b55cb03a478b26022ee.mpf_cache
2022-10-06 14:06:04,612 : INFO : ConfigProcessor : Loading config from cache: C:\Users\Tanner\AppData\Local\Temp\9cf7ccc27b21f4d6162237fadfc53e5a.mpf_cache
2022-10-06 14:06:04,613 : INFO : ConfigProcessor : Loading config from cache: C:\Users\Tanner\AppData\Local\Temp\c215df352878fee5d54f1a5ec5b16e7c.mpf_cache
2022-10-06 14:06:04,613 : INFO : ConfigProcessor : Loading config from cache: C:\Users\Tanner\AppData\Local\Temp\708062243e0edcfa77dd6b1521bd0d4e.mpf_cache
2022-10-06 14:06:04,614 : INFO : ConfigProcessor : Loading config from cache: C:\Users\Tanner\AppData\Local\Temp\c4174472f67f7b070dd6fb437c6feb0c.mpf_cache
2022-10-06 14:06:04,615 : INFO : ConfigProcessor : Loading config from cache: C:\Users\Tanner\AppData\Local\Temp\abaa92c43d134e3392cbb2346e6a16be.mpf_cache
2022-10-06 14:06:04,616 : INFO : ConfigProcessor : Loading config from cache: C:\Users\Tanner\AppData\Local\Temp\fc46d53fcb9fe6b8abf783d9c813390a.mpf_cache
2022-10-06 14:06:04,617 : INFO : Machine : Mission Pinball Framework Core Engine v0.55.0
2022-10-06 14:06:04,617 : INFO : Machine : Command line arguments: {'no_load_cache': False, 'create_config_cache': True, 'bcp': False, 'configfile': ['config.yaml'], 'force_assets_load': False, 'jsonlogging': False, 'logfile': 'logs\\2022-10-06-14-06-04-mpf-DESKTOP-7HNFDQ5.log', 'pause': False, 'production': False, 'text_ui': True, 'loglevel': 15, 'consoleloglevel': 20, 'force_platform': None, 'syslog_address': None, 'mc_file_name': None, 'no_sound': False}
2022-10-06 14:06:04,617 : INFO : Machine : MPF path: c:\users\tanner\appdata\local\programs\python\python37\lib\site-packages\mpf
2022-10-06 14:06:04,617 : INFO : Machine : Machine path: c:\trashland_2
2022-10-06 14:06:04,617 : INFO : Machine : Platform: win32
2022-10-06 14:06:04,617 : INFO : Machine : Python executable location: c:\users\tanner\appdata\local\programs\python\python37\python.exe
2022-10-06 14:06:04,617 : INFO : Machine : Python version: 3.7.8 (64-bit)
2022-10-06 14:06:04,619 : INFO : Machine : Initialise MPF.
2022-10-06 14:06:04,855 : INFO : FAST : Connecting to com9 at 921600bps
2022-10-06 14:06:04,887 : INFO : FAST : Connected! Processor: NET, Board Type: FP-CPU-002-2, Firmware: 01.05
2022-10-06 14:06:04,887 : INFO : EventManager : Event: ======'machine_var_fast_net_firmware'====== Args={'value': '01.05', 'prev_value': None, 'change': True}
2022-10-06 14:06:04,887 : INFO : EventManager : Event: ======'machine_var_fast_net_model'====== Args={'value': 'FP-CPU-002-2', 'prev_value': None, 'change': True}
2022-10-06 14:06:07,245 : WARNING : FAST : Got unexpected message from FAST: -N:30
2022-10-06 14:06:07,245 : WARNING : FAST : Got unexpected message from FAST: -N:38
2022-10-06 14:06:07,245 : WARNING : FAST : Got unexpected message from FAST: -N:40
2022-10-06 14:06:07,245 : WARNING : FAST : Got unexpected message from FAST: -N:41
2022-10-06 14:06:07,245 : WARNING : FAST : Got unexpected message from FAST: -N:42
2022-10-06 14:06:07,245 : WARNING : FAST : Got unexpected message from FAST: -N:43
2022-10-06 14:06:07,245 : WARNING : FAST : Got unexpected message from FAST: -N:44
2022-10-06 14:06:07,245 : WARNING : FAST : Got unexpected message from FAST: -N:5D
2022-10-06 14:06:07,355 : INFO : FAST : Connecting to com10 at 921600bps
2022-10-06 14:06:07,385 : INFO : FAST : Connected! Processor: RGB, Board Type: FP-CPU-002-2, Firmware: 00.87
2022-10-06 14:06:07,385 : INFO : EventManager : Event: ======'machine_var_fast_rgb_firmware'====== Args={'value': '00.87', 'prev_value': None, 'change': True}
2022-10-06 14:06:07,385 : INFO : EventManager : Event: ======'machine_var_fast_rgb_model'====== Args={'value': 'FP-CPU-002-2', 'prev_value': None, 'change': True}
2022-10-06 14:06:07,386 : INFO : EventManager : Event: ======'machine_var_credits_string'====== Args={'value': 'FREE PLAY', 'prev_value': None, 'change': True}
2022-10-06 14:06:07,429 : INFO : EventManager : Event: ======'machine_var_master_volume'====== Args={'value': 0.5, 'prev_value': None, 'change': True}
2022-10-06 14:06:07,429 : INFO : EventManager : Event: ======'machine_var_mpf_version'====== Args={'value': 'MPF v0.55.0', 'prev_value': None, 'change': True}
2022-10-06 14:06:07,429 : INFO : EventManager : Event: ======'machine_var_mpf_extended_version'====== Args={'value': 'MPF v0.55.0, Config version:5, Show version: 5, BCP version:1.1', 'prev_value': None, 'change': True}
2022-10-06 14:06:07,429 : INFO : EventManager : Event: ======'machine_var_python_version'====== Args={'value': '3.7.8', 'prev_value': None, 'change': True}
2022-10-06 14:06:07,429 : INFO : EventManager : Event: ======'machine_var_platform'====== Args={'value': 'Windows-10-10.0.19041-SP0', 'prev_value': None, 'change': True}
2022-10-06 14:06:07,429 : INFO : EventManager : Event: ======'machine_var_platform_system'====== Args={'value': 'Windows', 'prev_value': None, 'change': True}
2022-10-06 14:06:07,429 : INFO : EventManager : Event: ======'machine_var_platform_release'====== Args={'value': '10', 'prev_value': None, 'change': True}
2022-10-06 14:06:07,429 : INFO : EventManager : Event: ======'machine_var_platform_version'====== Args={'value': '10.0.19041', 'prev_value': None, 'change': True}
2022-10-06 14:06:07,429 : INFO : EventManager : Event: ======'machine_var_platform_machine'====== Args={'value': 'AMD64', 'prev_value': None, 'change': True}
2022-10-06 14:06:07,429 : INFO : EventManager : Event: ======'init_phase_1'====== Args={}
2022-10-06 14:06:07,467 : INFO : EventManager : Event: ======'drop_target_bank_mid_up'====== Args={}
2022-10-06 14:06:07,467 : INFO : EventManager : Event: ======'drop_target_bank_right_up'====== Args={}
2022-10-06 14:06:07,481 : ERROR : asyncio : Task exception was never retrieved
future: <Task finished coro=<SystemWideDevice.device_added_system_wide() done, defined at c:\users\tanner\appdata\local\programs\python\python37\lib\site-packages\mpf\core\system_wide_device.py:15> exception=AttributeError("'NoneType' object has no attribute 'name'")>
Traceback (most recent call last):
  File "c:\users\tanner\appdata\local\programs\python\python37\lib\site-packages\mpf\core\system_wide_device.py", line 17, in device_added_system_wide
    await self._initialize()
  File "c:\users\tanner\appdata\local\programs\python\python37\lib\site-packages\mpf\devices\ball_device\ball_device.py", line 90, in _initialize
    self._configure_targets()
  File "c:\users\tanner\appdata\local\programs\python\python37\lib\site-packages\mpf\devices\ball_device\ball_device.py", line 397, in _configure_targets
    if target.name == self.name:
AttributeError: 'NoneType' object has no attribute 'name'
2022-10-06 14:06:07,490 : ERROR : asyncio : Task exception was never retrieved
future: <Task finished coro=<SystemWideDevice.device_added_system_wide() done, defined at c:\users\tanner\appdata\local\programs\python\python37\lib\site-packages\mpf\core\system_wide_device.py:15> exception=AttributeError("'NoneType' object has no attribute 'is_playfield'")>
Traceback (most recent call last):
  File "c:\users\tanner\appdata\local\programs\python\python37\lib\site-packages\mpf\core\system_wide_device.py", line 17, in device_added_system_wide
    await self._initialize()
  File "c:\users\tanner\appdata\local\programs\python\python37\lib\site-packages\mpf\devices\ball_device\ball_device.py", line 90, in _initialize
    self._configure_targets()
  File "c:\users\tanner\appdata\local\programs\python\python37\lib\site-packages\mpf\devices\ball_device\ball_device.py", line 364, in _configure_targets
    self._validate_config()
  File "c:\users\tanner\appdata\local\programs\python\python37\lib\site-packages\mpf\devices\ball_device\ball_device.py", line 346, in _validate_config
    not self.find_path_to_target(self._target_on_unexpected_ball)):
  File "c:\users\tanner\appdata\local\programs\python\python37\lib\site-packages\mpf\devices\ball_device\ball_device.py", line 643, in find_path_to_target
    if target_device.is_playfield():
AttributeError: 'NoneType' object has no attribute 'is_playfield'
2022-10-06 14:06:07,491 : ERROR : asyncio : Task exception was never retrieved
future: <Task finished coro=<SystemWideDevice.device_added_system_wide() done, defined at c:\users\tanner\appdata\local\programs\python\python37\lib\site-packages\mpf\core\system_wide_device.py:15> exception=AttributeError("'NoneType' object has no attribute 'name'")>
Traceback (most recent call last):
  File "c:\users\tanner\appdata\local\programs\python\python37\lib\site-packages\mpf\core\system_wide_device.py", line 17, in device_added_system_wide
    await self._initialize()
  File "c:\users\tanner\appdata\local\programs\python\python37\lib\site-packages\mpf\devices\ball_device\ball_device.py", line 90, in _initialize
    self._configure_targets()
  File "c:\users\tanner\appdata\local\programs\python\python37\lib\site-packages\mpf\devices\ball_device\ball_device.py", line 397, in _configure_targets
    if target.name == self.name:
AttributeError: 'NoneType' object has no attribute 'name'
2022-10-06 14:06:07,491 : ERROR : asyncio : Task exception was never retrieved
future: <Task finished coro=<SystemWideDevice.device_added_system_wide() done, defined at c:\users\tanner\appdata\local\programs\python\python37\lib\site-packages\mpf\core\system_wide_device.py:15> exception=AttributeError("'NoneType' object has no attribute 'name'")>
Traceback (most recent call last):
  File "c:\users\tanner\appdata\local\programs\python\python37\lib\site-packages\mpf\core\system_wide_device.py", line 17, in device_added_system_wide
    await self._initialize()
  File "c:\users\tanner\appdata\local\programs\python\python37\lib\site-packages\mpf\devices\playfield.py", line 55, in _initialize
    if target.name == self.name:
AttributeError: 'NoneType' object has no attribute 'name'
2022-10-06 14:06:07,498 : INFO : EventManager : Event: ======'init_phase_2'====== Args={}
2022-10-06 14:06:07,498 : INFO : Machine : Starting the main run loop.
2022-10-06 14:06:07,501 : INFO : Machine : Shutting down...
2022-10-06 14:06:07,501 : INFO : EventManager : Event: ======'shutdown'====== Args={}
2022-10-06 14:06:07,502 : INFO : SwitchController : Found active switch: (('30', 1), <Platform.FAST>) <switch.s_drop_right_right>
2022-10-06 14:06:07,502 : INFO : SwitchController : Found active switch: (('34', 1), <Platform.FAST>) <switch.s_vuk_top>
2022-10-06 14:06:07,502 : INFO : SwitchController : Found active switch: (('33', 1), <Platform.FAST>) <switch.s_vuk_right>
2022-10-06 14:06:07,503 : INFO : SwitchController : Found active switch: (('48', 1), <Platform.FAST>) <switch.s_trough_1>
2022-10-06 14:06:07,503 : INFO : SwitchController : Found active switch: (('49', 1), <Platform.FAST>) <switch.s_trough_jam>
2022-10-06 14:06:07,503 : INFO : SwitchController : Found active switch: (('3C', 1), <Platform.FAST>) <switch.s_eos_right>
2022-10-06 14:06:07,504 : INFO : SwitchController : Found active switch: (('3B', 1), <Platform.FAST>) <switch.s_eos_left>
2022-10-06 14:06:07,547 : INFO : EventManager : Event: ======'init_phase_3'====== Args={}
2022-10-06 14:06:07,581 : INFO : EventManager : Event: ======'init_phase_4'====== Args={}
2022-10-06 14:06:07,582 : INFO : EventManager : Event: ======'playfield_active'====== Args={}
2022-10-06 14:06:07,583 : INFO : EventManager : Event: ======'unexpected_ball_on_playfield'====== Args={}
2022-10-06 14:06:07,583 : INFO : EventManager : Event: ======'playfield_active'====== Args={}
2022-10-06 14:06:07,583 : INFO : EventManager : Event: ======'unexpected_ball_on_playfield'====== Args={}
2022-10-06 14:06:07,584 : INFO : EventManager : Event: ======'playfield_active'====== Args={}
2022-10-06 14:06:07,584 : INFO : EventManager : Event: ======'unexpected_ball_on_playfield'====== Args={}
2022-10-06 14:06:07,585 : INFO : EventManager : Event: ======'playfield_active'====== Args={}
2022-10-06 14:06:07,585 : INFO : EventManager : Event: ======'unexpected_ball_on_playfield'====== Args={}
2022-10-06 14:06:07,586 : INFO : EventManager : Event: ======'playfield_active'====== Args={}
2022-10-06 14:06:07,586 : INFO : EventManager : Event: ======'unexpected_ball_on_playfield'====== Args={}
2022-10-06 14:06:07,586 : INFO : EventManager : Event: ======'drop_target_right_right_down'====== Args={'device': <drop_target.right_right>}
2022-10-06 14:06:07,587 : INFO : EventManager : Event: ======'drop_target_bank_right_mixed'====== Args={'prev_value': <DropTargetBankState.UP: 'up'>, 'down': 1}
2022-10-06 14:06:07,587 : INFO : EventManager : Event: ======'playfield_active'====== Args={}
2022-10-06 14:06:07,588 : INFO : EventManager : Event: ======'unexpected_ball_on_playfield'====== Args={}
2022-10-06 14:06:07,607 : ERROR : asyncio : Exception in callback Util.raise_exceptions(<Task finishe...e 'counter'")>) at c:\users\tanner\appdata\local\programs\python\python37\lib\site-packages\mpf\core\utility_functions.py:752
handle: <Handle Util.raise_exceptions(<Task finishe...e 'counter'")>) at c:\users\tanner\appdata\local\programs\python\python37\lib\site-packages\mpf\core\utility_functions.py:752>
Traceback (most recent call last):
  File "c:\users\tanner\appdata\local\programs\python\python37\lib\asyncio\events.py", line 88, in _run
    self._context.run(self._callback, *self._args)
  File "c:\users\tanner\appdata\local\programs\python\python37\lib\site-packages\mpf\core\utility_functions.py", line 760, in raise_exceptions
    future.result()
  File "c:\users\tanner\appdata\local\programs\python\python37\lib\site-packages\mpf\core\ball_controller.py", line 90, in _add_new_balls_to_playfield
    self.num_balls_known = await self._count_all_balls_in_devices()
  File "c:\users\tanner\appdata\local\programs\python\python37\lib\site-packages\mpf\core\ball_controller.py", line 129, in _count_all_balls_in_devices
    futures.append(asyncio.ensure_future(device.ball_count_handler.counter.wait_for_count_stable()))
AttributeError: 'NoneType' object has no attribute 'counter'
2022-10-06 14:06:07,620 : ERROR : FAST : Stop called on serial connection com9
2022-10-06 14:06:07,620 : ERROR : FAST : Stop called on serial connection com10
2022-10-06 14:06:07,838 : ERROR : asyncio : Task was destroyed but it is pending!
task: <Task pending coro=<wait() running at c:\users\tanner\appdata\local\programs\python\python37\lib\asyncio\tasks.py:389> wait_for=<Future finished result=None> cb=[Bcp._setup_bcp_servers.<locals>.<lambda>() at c:\users\tanner\appdata\local\programs\python\python37\lib\site-packages\mpf\core\bcp\bcp.py:113]>
2022-10-06 14:06:07,838 : ERROR : asyncio : Task was destroyed but it is pending!
task: <Task pending coro=<Event.wait() running at c:\users\tanner\appdata\local\programs\python\python37\lib\asyncio\locks.py:293> wait_for=<Future cancelled>>
2022-10-06 14:06:07,839 : ERROR : asyncio : Task was destroyed but it is pending!
task: <Task pending coro=<Event.wait() running at c:\users\tanner\appdata\local\programs\python\python37\lib\asyncio\locks.py:293> wait_for=<Future cancelled>>
2022-10-06 14:06:07,840 : ERROR : Machine : Runtime Exception
Traceback (most recent call last):
  File "c:\users\tanner\appdata\local\programs\python\python37\lib\site-packages\mpf\core\machine.py", line 769, in _run_loop
    raise self._exception['exception']
  File "c:\users\tanner\appdata\local\programs\python\python37\lib\site-packages\mpf\core\system_wide_device.py", line 17, in device_added_system_wide
    await self._initialize()
  File "c:\users\tanner\appdata\local\programs\python\python37\lib\site-packages\mpf\devices\ball_device\ball_device.py", line 90, in _initialize
    self._configure_targets()
  File "c:\users\tanner\appdata\local\programs\python\python37\lib\site-packages\mpf\devices\ball_device\ball_device.py", line 397, in _configure_targets
    if target.name == self.name:
AttributeError: 'NoneType' object has no attribute 'name'
2022-10-06 14:06:17,600 : ERROR : root : 
Traceback (most recent call last):
  File "c:\users\tanner\appdata\local\programs\python\python37\lib\site-packages\mpf\core\machine.py", line 769, in _run_loop
    raise self._exception['exception']
  File "c:\users\tanner\appdata\local\programs\python\python37\lib\site-packages\mpf\core\system_wide_device.py", line 17, in device_added_system_wide
    await self._initialize()
  File "c:\users\tanner\appdata\local\programs\python\python37\lib\site-packages\mpf\devices\ball_device\ball_device.py", line 90, in _initialize
    self._configure_targets()
  File "c:\users\tanner\appdata\local\programs\python\python37\lib\site-packages\mpf\devices\ball_device\ball_device.py", line 397, in _configure_targets
    if target.name == self.name:
AttributeError: 'NoneType' object has no attribute 'name'

During handling of the above exception, another exception occurred:

Traceback (most recent call last):
  File "c:\users\tanner\appdata\local\programs\python\python37\lib\site-packages\mpf\commands\game.py", line 239, in __init__
    self.machine.run()
  File "c:\users\tanner\appdata\local\programs\python\python37\lib\site-packages\mpf\core\machine.py", line 687, in run
    self._run_loop()
  File "c:\users\tanner\appdata\local\programs\python\python37\lib\site-packages\mpf\core\machine.py", line 772, in _run_loop
    report_crash(self._exception['exception'], "exception_during_run", self.config)
  File "c:\users\tanner\appdata\local\programs\python\python37\lib\site-packages\mpf\core\crash_reporter.py", line 236, in report_crash
    response = input("Do you want to report the crash to the MPF team (yes/no/show)? ")
EOFError
